Workbook

Sheet 【国内】特殊&小众用户招募-数据源
A1: 特殊用户数据源
A2: 一级难度 | F2: 600 | G2: 已知成本 | H2: 二级难度 | M2: 750 | N2: 已知成本 | O2: 三级难度 | T2: 950 | V2: 四级难度 | AA2: 1000 | AC2: =AVERAGE(F2,M2,T2,AA2) -> 825 | AD2: 市场价：1100
A3: 样本数 | B3: P5 | C3: P3 | D3: OP | E3: 实习 | F3: =AVERAGE(F5:F14) -> 650 | H3: 样本数 | I3: P5 | J3: P3 | K3: OP | L3: 实习 | O3: 样本数 | P3: P5 | Q3: P3 | R3: OP | S3: 实习 | V3: 样本数 | W3: P5 | X3: P3 | Y3: OP | Z3: 实习
A4: 0 | B4: 0 | C4: =(G4*A4-B4*5900-D4*1200-E4*300)/3400 -> 0 | D4: ='【国内】常规用户招募-数据源(正职+OP混合执行）'!AC4*2 -> 0 | E4: 0 | G4: 650 | H4: 0 | I4: 0 | J4: =(N4*H4-I4*5900-K4*1200-L4*300)/3400 -> 0 | K4: ='【国内】常规用户招募-数据源(正职+OP混合执行）'!AO4*2.2 -> 0 | L4: 0 | N4: 750 | O4: 0 | P4: 0 | Q4: =(U4*O4-P4*5900-R4*1200-S4*300)/3400 -> 0 | R4: ='【国内】常规用户招募-数据源(正职+OP混合执行）'!BA4*2.3 -> 0 | S4: 0 | T4: =(P4*7200+R4*3200+S4*300+(800+300)*O4)/O4 -> #DIV/0! | U4: 950 | V4: 0 | W4: 0 | X4: =(AB4*V4-W4*5900-Y4*1200-Z4*300)/3400 -> 0 | Y4: =R4*1.2 -> 0 | Z4: 0 | AA4: =(W4*7200+Y4*3200+Z4*300+(800+300)*V4)/V4 -> #DIV/0! | AB4: 1000
A5: 1 | B5: 0 | C5: =(G5*A5-B5*5900-D5*1200-E5*300)/3400 -> 0.12529412 | D5: ='【国内】常规用户招募-数据源(正职+OP混合执行）'!AC5*2 -> 0.18666667 | E5: 0 | F5: =(B5*5900+C5*3400+D5*1200+E5*300)/A5 -> 650 | G5: 650 | H5: 1 | I5: 0 | J5: =(N5*H5-I5*5900-K5*1200-L5*300)/3400 -> 0.066475294 | K5: ='【国内】常规用户招募-数据源(正职+OP混合执行）'!AO5*2.2 -> 0.26165333 | L5: 0.7 | M5: =(I5*5900+J5*3400+K5*1200+L5*300)/H5 -> 750 | N5: 750 | O5: 1 | P5: 0 | Q5: =(U5*O5-P5*5900-R5*1200-S5*300)/3400 -> 0.040176471 | R5: ='【国内】常规用户招募-数据源(正职+OP混合执行）'!BA5*2.3 -> 0.30283333 | S5: 1.5 | T5: =(P5*5900+Q5*3400+R5*1200+S5*300)/O5 -> 950 | U5: 950 | V5: 1 | W5: 0 | X5: =(AB5*V5-W5*5900-Y5*1200-Z5*300)/3400 -> 0.046331765 | Y5: =R5*1.08 -> 0.32706 | Z5: 1.5 | AA5: =(W5*5900+X5*3400+Y5*1200+Z5*300)/V5 -> 1000 | AB5: 1000
A6: 2 | B6: 0 | C6: =(G6*A6-B6*5900-D6*1200-E6*300)/3400 -> 0.15294118 | D6: 0.5 | E6: 0.6 | F6: =(B6*5900+C6*3400+D6*1200+E6*300)/A6 -> 650 | G6: 650 | H6: 2 | I6: 0 | J6: =(N6*H6-I6*5900-K6*1200-L6*300)/3400 -> 0.065025882 | K6: ='【国内】常规用户招募-数据源(正职+OP混合执行）'!AO6*2.2 -> 0.81576 | L6: 1 | M6: =(I6*5900+J6*3400+K6*1200+L6*300)/H6 -> 750 | N6: 750 | O6: 2 | P6: 0 | Q6: =(U6*O6-P6*5900-R6*1200-S6*300)/3400 -> 0.065147059 | R6: ='【国内】常规用户招募-数据源(正职+OP混合执行）'!BA6*2.3 -> 0.94875 | S6: 1.8 | T6: =(P6*5900+Q6*3400+R6*1200+S6*300)/O6 -> 950 | U6: 950 | V6: 2 | W6: 0 | X6: =(AB6*V6-W6*5900-Y6*1200-Z6*300)/3400 -> 0.067770588 | Y6: =R6*1.08 -> 1.02465 | Z6: 1.8 | AA6: =(W6*5900+X6*3400+Y6*1200+Z6*300)/V6 -> 1000 | AB6: 1000
A7: 3 | B7: 0 | C7: =(G7*A7-B7*5900-D7*1200-E7*300)/3400 -> 0.26470588 | D7: 0.7 | E7: 0.7 | F7: =(B7*5900+C7*3400+D7*1200+E7*300)/A7 -> 650 | G7: 650 | H7: 3 | I7: 0 | J7: =(N7*H7-I7*5900-K7*1200-L7*300)/3400 -> 0.22058824 | K7: 1 | L7: 1 | M7: =(I7*5900+J7*3400+K7*1200+L7*300)/H7 -> 750 | N7: 750 | O7: 3 | P7: 0 | Q7: =(U7*O7-P7*5900-R7*1200-S7*300)/3400 -> 0.20035294 | R7: ='【国内】常规用户招募-数据源(正职+OP混合执行）'!BA7*2.3 -> 1.2573333 | S7: 2.2 | T7: =(P7*5900+Q7*3400+R7*1200+S7*300)/O7 -> 950 | U7: 950 | V7: 3 | W7: 0 | X7: =(AB7*V7-W7*5900-Y7*1200-Z7*300)/3400 -> 0.20896941 | Y7: =R7*1.08 -> 1.35792 | Z7: 2.2 | AA7: =(W7*5900+X7*3400+Y7*1200+Z7*300)/V7 -> 1000 | AB7: 1000
A8: 4 | B8: 0 | C8: =(G8*A8-B8*5900-D8*1200-E8*300)/3400 -> 0.24588235 | D8: ='【国内】常规用户招募-数据源(正职+OP混合执行）'!AC8*2 -> 1.27 | E8: 0.8 | F8: =(B8*5900+C8*3400+D8*1200+E8*300)/A8 -> 650 | G8: 650 | H8: 4 | I8: =P8/2 -> 0.05 | J8: =(N8*H8-I8*5900-K8*1200-L8*300)/3400 -> 0.13911765 | K8: 1.5 | L8: =S8*0.6 -> 1.44 | M8: =(I8*5900+J8*3400+K8*1200+L8*300)/H8 -> 750 | N8: 750 | O8: 4 | P8: 0.1 | Q8: =(U8*O8-P8*5900-R8*1200-S8*300)/3400 -> 0.097058824 | R8: 1.8 | S8: 2.4 | T8: =(P8*5900+Q8*3400+R8*1200+S8*300)/O8 -> 950 | U8: 950 | V8: 4 | W8: 0.1 | X8: =(AB8*V8-W8*5900-Y8*1200-Z8*300)/3400 -> 0.10505882 | Y8: =R8*1.08 -> 1.944 | Z8: 2.4 | AA8: =(W8*5900+X8*3400+Y8*1200+Z8*300)/V8 -> 1000 | AB8: 1000
A9: 5 | B9: 0 | C9: =(G9*A9-B9*5900-D9*1200-E9*300)/3400 -> 0.38235294 | D9: 1.4 | E9: 0.9 | F9: =(B9*5900+C9*3400+D9*1200+E9*300)/A9 -> 650 | G9: 650 | H9: 5 | I9: =P9/2 -> 0.05 | J9: =(N9*H9-I9*5900-K9*1200-L9*300)/3400 -> 0.31382353 | K9: 1.6 | L9: =S9*0.6 -> 1.56 | M9: =(I9*5900+J9*3400+K9*1200+L9*300)/H9 -> 750 | N9: 750 | O9: 5 | P9: 0.1 | Q9: =(U9*O9-P9*5900-R9*1200-S9*300)/3400 -> 0.32352941 | R9: 1.9 | S9: 2.6 | T9: =(P9*5900+Q9*3400+R9*1200+S9*300)/O9 -> 950 | U9: 950 | V9: 5 | W9: 0.1 | X9: =(AB9*V9-W9*5900-Y9*1200-Z9*300)/3400 -> 0.34341176 | Y9: =R9*1.08 -> 2.052 | Z9: 2.6 | AA9: =(W9*5900+X9*3400+Y9*1200+Z9*300)/V9 -> 1000 | AB9: 1000
A10: 6 | B10: 0 | C10: =(G10*A10-B10*5900-D10*1200-E10*300)/3400 -> 0.49411765 | D10: 1.6 | E10: 1 | F10: =(B10*5900+C10*3400+D10*1200+E10*300)/A10 -> 650 | G10: 650 | H10: 6 | I10: =P10/2 -> 0.1 | J10: =(N10*H10-I10*5900-K10*1200-L10*300)/3400 -> 0.40705882 | K10: 1.7 | L10: =S10*0.6 -> 1.62 | M10: =(I10*5900+J10*3400+K10*1200+L10*300)/H10 -> 750 | N10: 750 | O10: 6 | P10: 0.2 | Q10: =(U10*O10-P10*5900-R10*1200-S10*300)/3400 -> 0.38529412 | R10: 2 | S10: 2.7 | T10: =(P10*5900+Q10*3400+R10*1200+S10*300)/O10 -> 950 | U10: 950 | V10: 6 | W10: 0.2 | X10: =(AB10*V10-W10*5900-Y10*1200-Z10*300)/3400 -> 0.41705882 | Y10: =R10*1.08 -> 2.16 | Z10: 2.7 | AA10: =(W10*5900+X10*3400+Y10*1200+Z10*300)/V10 -> 1000 | AB10: 1000
A11: 7 | B11: 0 | C11: =(G11*A11-B11*5900-D11*1200-E11*300)/3400 -> 0.53529412 | D11: 2 | E11: 1.1 | F11: =(B11*5900+C11*3400+D11*1200+E11*300)/A11 -> 650 | G11: 650 | H11: 7 | I11: =P11/2 -> 0.1 | J11: =(N11*H11-I11*5900-K11*1200-L11*300)/3400 -> 0.50588235 | K11: 2 | L11: =S11*0.6 -> 1.8 | M11: =(I11*5900+J11*3400+K11*1200+L11*300)/H11 -> 750 | N11: 750 | O11: 7 | P11: 0.2 | Q11: =(U11*O11-P11*5900-R11*1200-S11*300)/3400 -> 0.56764706 | R11: 2.2 | S11: 3 | T11: =(P11*5900+Q11*3400+R11*1200+S11*300)/O11 -> 950 | U11: 950 | V11: 7 | W11: 0.2 | X11: =(AB11*V11-W11*5900-Y11*1200-Z11*300)/3400 -> 0.60847059 | Y11: =R11*1.08 -> 2.376 | Z11: 3 | AA11: =(W11*5900+X11*3400+Y11*1200+Z11*300)/V11 -> 1000 | AB11: 1000
A12: 8 | B12: 0 | C12: =(G12*A12-B12*5900-D12*1200-E12*300)/3400 -> 0.62058824 | D12: 2.2 | E12: 1.5 | F12: =(B12*5900+C12*3400+D12*1200+E12*300)/A12 -> 650 | G12: 650 | H12: 8 | I12: =P12/2 -> 0.1 | J12: =(N12*H12-I12*5900-K12*1200-L12*300)/3400 -> 0.64529412 | K12: 2.2 | L12: =S12*0.6 -> 1.92 | M12: =(I12*5900+J12*3400+K12*1200+L12*300)/H12 -> 750 | N12: 750 | O12: 8 | P12: 0.2 | Q12: =(U12*O12-P12*5900-R12*1200-S12*300)/3400 -> 0.75882353 | R12: 2.4 | S12: 3.2 | T12: =(P12*5900+Q12*3400+R12*1200+S12*300)/O12 -> 950 | U12: 950 | V12: 8 | W12: 0.2 | X12: =(AB12*V12-W12*5900-Y12*1200-Z12*300)/3400 -> 0.80870588 | Y12: =R12*1.08 -> 2.592 | Z12: 3.2 | AA12: =(W12*5900+X12*3400+Y12*1200+Z12*300)/V12 -> 1000 | AB12: 1000
A13: 9 | B13: 0 | C13: =(G13*A13-B13*5900-D13*1200-E13*300)/3400 -> 0.66176471 | D13: 2.5 | E13: 2 | F13: =(B13*5900+C13*3400+D13*1200+E13*300)/A13 -> 650 | G13: 650 | H13: 9 | I13: =P13/2 -> 0.1 | J13: =(N13*H13-I13*5900-K13*1200-L13*300)/3400 -> 0.73882353 | K13: 2.5 | L13: =S13*0.6 -> 2.16 | M13: =(I13*5900+J13*3400+K13*1200+L13*300)/H13 -> 750 | N13: 750 | O13: 9 | P13: 0.2 | Q13: =(U13*O13-P13*5900-R13*1200-S13*300)/3400 -> 0.93235294 | R13: 2.6 | S13: 3.6 | T13: =(P13*5900+Q13*3400+R13*1200+S13*300)/O13 -> 950 | U13: 950 | V13: 9 | W13: 0.2 | X13: =(AB13*V13-W13*5900-Y13*1200-Z13*300)/3400 -> 0.99129412 | Y13: =R13*1.08 -> 2.808 | Z13: 3.6 | AA13: =(W13*5900+X13*3400+Y13*1200+Z13*300)/V13 -> 1000 | AB13: 1000
A14: 10 | B14: 0 | C14: =(G14*A14-B14*5900-D14*1200-E14*300)/3400 -> 0.72941176 | D14: 2.8 | E14: 2.2 | F14: =(B14*5900+C14*3400+D14*1200+E14*300)/A14 -> 650 | G14: 650 | H14: 10 | I14: =P14/2 -> 0.1 | J14: =(N14*H14-I14*5900-K14*1200-L14*300)/3400 -> 0.84294118 | K14: 2.8 | L14: =S14*0.6 -> 2.28 | M14: =(I14*5900+J14*3400+K14*1200+L14*300)/H14 -> 750 | N14: 750 | O14: 10 | P14: 0.2 | Q14: =(U14*O14-P14*5900-R14*1200-S14*300)/3400 -> 1.1235294 | R14: 2.8 | S14: 3.8 | T14: =(P14*5900+Q14*3400+R14*1200+S14*300)/O14 -> 950 | U14: 950 | V14: 10 | W14: 0.2 | X14: =(AB14*V14-W14*5900-Y14*1200-Z14*300)/3400 -> 1.1915294 | Y14: =R14*1.08 -> 3.024 | Z14: 3.8 | AA14: =(W14*5900+X14*3400+Y14*1200+Z14*300)/V14 -> 1000 | AB14: 1000
A15: 线下礼金 | H15: 线下礼金 | O15: 线下礼金 | V15: 线下礼金
A16: 2小时及以内玩家礼金 | E16: 800 | H16: 2小时及以内玩家礼金 | L16: 800 | O16: 2小时及以内玩家礼金 | S16: 1000 | V16: 2小时及以内玩家礼金 | Z16: 1200
A17: 每增加0.5小时，礼金+200 | H17: 每增加0.5小时，礼金+200 | O17: 每增加0.5小时，礼金+250 | V17: 每增加0.5小时，礼金+300
A18: 线上礼金 | H18: 线上礼金 | O18: 线上礼金 | V18: 线上礼金
A19: 2小时及以内玩家礼金 | E19: 300 | H19: 2小时及以内玩家礼金 | L19: 400 | O19: 2小时及以内玩家礼金 | S19: 500 | V19: 2小时及以内玩家礼金 | Z19: 600
A20: 每增加0.5小时，礼金+70 | H20: 每增加0.5小时，礼金+100 | O20: 每增加0.5小时，礼金+120 | V20: 每增加0.5小时，礼金+150
A22: 小众用户数据源
A23: 一级难度 | F23: =AVERAGE(F26:F35) -> 1200 | G23: 已知成本 | H23: 二级难度 | M23: =AVERAGE(M26:M35) -> 1400 | O23: 三级难度 | T23: =AVERAGE(T26:T35) -> 1500 | V23: 四级难度 | AA23: =AVERAGE(AA26:AA35) -> 1800 | AC23: =AVERAGE(F23,M23,T23,AA23) -> 1475
A24: 样本数 | B24: P5 | C24: P3 | D24: OP | E24: 实习 | H24: 样本数 | I24: P5 | J24: P3 | K24: OP | L24: 实习 | O24: 样本数 | P24: P5 | Q24: P3 | R24: OP | S24: 实习 | V24: 样本数 | W24: P5 | X24: P3 | Y24: OP | Z24: 实习
A25: 0 | B25: 0 | C25: =(G25*A25-B25*5900-E25*300)/3400 -> 0 | D25: 0 | E25: 0 | F25: =(B25*7200+D25*3200+E25*300+(450+400)*A25)/A25 -> #DIV/0! | G25: 1200 | H25: 0 | I25: =B25*1.15 -> 0 | J25: =(N25*H25-I25*5900-L25*300)/3400 -> 0 | K25: =D25*1.15 -> 0 | L25: 0 | M25: =(I25*7200+K25*3200+L25*300+(450+400)*H25)/H25 -> #DIV/0! | N25: 1400 | O25: 0 | P25: =I25*1.2 -> 0 | Q25: =(U25*O25-P25*5900-S25*300)/3400 -> 0 | R25: 0 | S25: 0 | T25: =(P25*7200+R25*3200+S25*300+(450+400)*O25)/O25 -> #DIV/0! | U25: 1500 | V25: 0 | W25: 0 | X25: =(AB25*V25-W25*5900-Z25*300)/3400 -> 0 | Y25: 0 | Z25: 0 | AA25: =(W25*7200+Y25*3200+Z25*300+(450+400)*V25)/V25 -> #DIV/0! | AB25: 1800
A26: 1 | B26: 0 | C26: =(G26*A26-B26*5900-E26*300)/3400 -> 0.35294118 | D26: 0 | E26: 0 | F26: =(B26*5900+C26*3400+E26*300)/A26 -> 1200 | G26: 1200 | H26: 1 | I26: =B26*1.15 -> 0 | J26: =(N26*H26-I26*5900-L26*300)/3400 -> 0.23529412 | K26: =D26*1.15 -> 0 | L26: 2 | M26: =(I26*5900+J26*3400+L26*300)/H26 -> 1400 | N26: 1400 | O26: 1 | P26: 0 | Q26: =(U26*O26-P26*5900-S26*300)/3400 -> 0.26470588 | R26: =K26*1.3 -> 0 | S26: 2 | T26: =(P26*5900+Q26*3400+S26*300)/O26 -> 1500 | U26: 1500 | V26: 1 | W26: 0 | X26: =(AB26*V26-W26*5900-Z26*300)/3400 -> 0.35294118 | Y26: =R26*1.2 -> 0 | Z26: 2 | AA26: =(W26*5900+X26*3400+Z26*300)/V26 -> 1800 | AB26: =U26*1.2 -> 1800
A27: 2 | B27: 0.1 | C27: =(G27*A27-B27*5900-E27*300)/3400 -> 0.35588235 | D27: 0 | E27: 2 | F27: =(B27*5900+C27*3400+E27*300)/A27 -> 1200 | G27: 1200 | H27: 2 | I27: =B27*1.15 -> 0.115 | J27: =(N27*H27-I27*5900-L27*300)/3400 -> 0.40338235 | K27: =D27*1.2 -> 0 | L27: 2.5 | M27: =(I27*5900+J27*3400+L27*300)/H27 -> 1400 | N27: 1400 | O27: 2 | P27: 0.1 | Q27: =(U27*O27-P27*5900-S27*300)/3400 -> 0.48823529 | R27: =K27*1.3 -> 0 | S27: 2.5 | T27: =(P27*5900+Q27*3400+S27*300)/O27 -> 1500 | U27: 1500 | V27: 2 | W27: 0.1 | X27: =(AB27*V27-W27*5900-Z27*300)/3400 -> 0.66470588 | Y27: =R27*1.2 -> 0 | Z27: 2.5 | AA27: =(W27*5900+X27*3400+Z27*300)/V27 -> 1800 | AB27: =U27*1.2 -> 1800
A28: 3 | B28: 0.1 | C28: =(G28*A28-B28*5900-E28*300)/3400 -> 0.7 | D28: 0 | E28: 2.1 | F28: =(B28*5900+C28*3400+E28*300)/A28 -> 1200 | G28: 1200 | H28: 3 | I28: =B28*1.15 -> 0.115 | J28: =(N28*H28-I28*5900-L28*300)/3400 -> 0.81514706 | K28: =D28*1.2 -> 0 | L28: 2.5 | M28: =(I28*5900+J28*3400+L28*300)/H28 -> 1400 | N28: 1400 | O28: 3 | P28: =I28*1.5 -> 0.1725 | Q28: =(U28*O28-P28*5900-S28*300)/3400 -> 0.80360294 | R28: =K28*1.3 -> 0 | S28: 2.5 | T28: =(P28*5900+Q28*3400+S28*300)/O28 -> 1500 | U28: 1500 | V28: 3 | W28: 0.1725 | X28: =(AB28*V28-W28*5900-Z28*300)/3400 -> 1.0683088 | Y28: =R28*1.2 -> 0 | Z28: 2.5 | AA28: =(W28*5900+X28*3400+Z28*300)/V28 -> 1800 | AB28: =U28*1.2 -> 1800
A29: 4 | B29: 0.1 | C29: =(G29*A29-B29*5900-E29*300)/3400 -> 1.0441176 | D29: 0 | E29: 2.2 | F29: =(B29*5900+C29*3400+E29*300)/A29 -> 1200 | G29: 1200 | H29: 4 | I29: =B29*1.15 -> 0.115 | J29: =(N29*H29-I29*5900-L29*300)/3400 -> 1.2269118 | K29: =D29*1.2 -> 0 | L29: 2.5 | M29: =(I29*5900+J29*3400+L29*300)/H29 -> 1400 | N29: 1400 | O29: 4 | P29: =I29*1.5 -> 0.1725 | Q29: =(U29*O29-P29*5900-S29*300)/3400 -> 1.2447794 | R29: =K29*1.3 -> 0 | S29: 2.5 | T29: =(P29*5900+Q29*3400+S29*300)/O29 -> 1500 | U29: 1500 | V29: 4 | W29: 0.1725 | X29: =(AB29*V29-W29*5900-Z29*300)/3400 -> 1.5977206 | Y29: =R29*1.2 -> 0 | Z29: 2.5 | AA29: =(W29*5900+X29*3400+Z29*300)/V29 -> 1800 | AB29: =U29*1.2 -> 1800
A30: 5 | B30: =0.1*1.5 -> 0.15 | C30: =(G30*A30-B30*5900-E30*300)/3400 -> 1.2838235 | D30: 0 | E30: 2.5 | F30: =(B30*5900+C30*3400+E30*300)/A30 -> 1200 | G30: 1200 | H30: 5 | I30: =B30*1.15 -> 0.1725 | J30: =(N30*H30-I30*5900-L30*300)/3400 -> 1.4947794 | K30: =D30*1.2 -> 0 | L30: 3 | M30: =(I30*5900+J30*3400+L30*300)/H30 -> 1400 | N30: 1400 | O30: 5 | P30: 0.2 | Q30: =(U30*O30-P30*5900-S30*300)/3400 -> 1.5941176 | R30: =K30*1.3 -> 0 | S30: 3 | T30: =(P30*5900+Q30*3400+S30*300)/O30 -> 1500 | U30: 1500 | V30: 5 | W30: 0.25875 | X30: =(AB30*V30-W30*5900-Z30*300)/3400 -> 1.9333456 | Y30: =R30*1.2 -> 0 | Z30: 3 | AA30: =(W30*5900+X30*3400+Z30*300)/V30 -> 1800 | AB30: =U30*1.2 -> 1800
A31: 6 | B31: =0.1*1.5 -> 0.15 | C31: =(G31*A31-B31*5900-E31*300)/3400 -> 1.6191176 | D31: 0 | E31: 2.7 | F31: =(B31*5900+C31*3400+E31*300)/A31 -> 1200 | G31: 1200 | H31: 6 | I31: =B31*1.15 -> 0.1725 | J31: =(N31*H31-I31*5900-L31*300)/3400 -> 1.9065441 | K31: =D31*1.2 -> 0 | L31: 3 | M31: =(I31*5900+J31*3400+L31*300)/H31 -> 1400 | N31: 1400 | O31: 6 | P31: 0.2 | Q31: =(U31*O31-P31*5900-S31*300)/3400 -> 2.0352941 | R31: =K31*1.3 -> 0 | S31: 3 | T31: =(P31*5900+Q31*3400+S31*300)/O31 -> 1500 | U31: 1500 | V31: 6 | W31: 0.25875 | X31: =(AB31*V31-W31*5900-Z31*300)/3400 -> 2.4627574 | Y31: =R31*1.2 -> 0 | Z31: 3 | AA31: =(W31*5900+X31*3400+Z31*300)/V31 -> 1800 | AB31: =U31*1.2 -> 1800
A32: 7 | B32: =0.1*1.5 -> 0.15 | C32: =(G32*A32-B32*5900-E32*300)/3400 -> 1.9455882 | D32: 0 | E32: 3 | F32: =(B32*5900+C32*3400+E32*300)/A32 -> 1200 | G32: 1200 | H32: 7 | I32: =B32*1.15 -> 0.1725 | J32: =(N32*H32-I32*5900-L32*300)/3400 -> 2.3183088 | K32: =D32*1.2 -> 0 | L32: 3 | M32: =(I32*5900+J32*3400+L32*300)/H32 -> 1400 | N32: 1400 | O32: 7 | P32: =I32*1.5 -> 0.25875 | Q32: =(U32*O32-P32*5900-S32*300)/3400 -> 2.3745221 | R32: =K32*1.3 -> 0 | S32: 3 | T32: =(P32*5900+Q32*3400+S32*300)/O32 -> 1500 | U32: 1500 | V32: 7 | W32: 0.25875 | X32: =(AB32*V32-W32*5900-Z32*300)/3400 -> 2.9921691 | Y32: =R32*1.2 -> 0 | Z32: 3 | AA32: =(W32*5900+X32*3400+Z32*300)/V32 -> 1800 | AB32: =U32*1.2 -> 1800
A33: 8 | B33: =0.1*1.5 -> 0.15 | C33: =(G33*A33-B33*5900-E33*300)/3400 -> 2.2897059 | D33: 0 | E33: 3.1 | F33: =(B33*5900+C33*3400+E33*300)/A33 -> 1200 | G33: 1200 | H33: 8 | I33: =B33*1.15 -> 0.1725 | J33: =(N33*H33-I33*5900-L33*300)/3400 -> 2.6859559 | K33: =D33*1.2 -> 0 | L33: 3.5 | M33: =(I33*5900+J33*3400+L33*300)/H33 -> 1400 | N33: 1400 | O33: 8 | P33: =I33*1.5 -> 0.25875 | Q33: =(U33*O33-P33*5900-S33*300)/3400 -> 2.7715809 | R33: =K33*1.3 -> 0 | S33: 3.5 | T33: =(P33*5900+Q33*3400+S33*300)/O33 -> 1500 | U33: 1500 | V33: 8 | W33: 0.25875 | X33: =(AB33*V33-W33*5900-Z33*300)/3400 -> 3.4774632 | Y33: =R33*1.2 -> 0 | Z33: 3.5 | AA33: =(W33*5900+X33*3400+Z33*300)/V33 -> 1800 | AB33: =U33*1.2 -> 1800
A34: 9 | B34: =0.1*1.5 -> 0.15 | C34: =(G34*A34-B34*5900-E34*300)/3400 -> 2.6073529 | D34: 0 | E34: 3.5 | F34: =(B34*5900+C34*3400+E34*300)/A34 -> 1200 | G34: 1200 | H34: 9 | I34: =B34*1.15 -> 0.1725 | J34: =(N34*H34-I34*5900-L34*300)/3400 -> 3.0536029 | K34: =D34*1.2 -> 0 | L34: 4 | M34: =(I34*5900+J34*3400+L34*300)/H34 -> 1400 | N34: 1400 | O34: 9 | P34: =I34*1.5 -> 0.25875 | Q34: =(U34*O34-P34*5900-S34*300)/3400 -> 3.1686397 | R34: =K34*1.3 -> 0 | S34: 4 | T34: =(P34*5900+Q34*3400+S34*300)/O34 -> 1500 | U34: 1500 | V34: 9 | W34: 0.25875 | X34: =(AB34*V34-W34*5900-Z34*300)/3400 -> 3.9627574 | Y34: =R34*1.2 -> 0 | Z34: 4 | AA34: =(W34*5900+X34*3400+Z34*300)/V34 -> 1800 | AB34: =U34*1.2 -> 1800
A35: 10 | B35: =0.1*1.5 -> 0.15 | C35: =(G35*A35-B35*5900-E35*300)/3400 -> 2.9602941 | D35: 0 | E35: 3.5 | F35: =(B35*5900+C35*3400+E35*300)/A35 -> 1200 | G35: 1200 | H35: 10 | I35: =B35*1.15 -> 0.1725 | J35: =(N35*H35-I35*5900-L35*300)/3400 -> 3.4653676 | K35: =D35*1.2 -> 0 | L35: 4 | M35: =(I35*5900+J35*3400+L35*300)/H35 -> 1400 | N35: 1400 | O35: 10 | P35: =I35*1.5 -> 0.25875 | Q35: =(U35*O35-P35*5900-S35*300)/3400 -> 3.6098162 | R35: =K35*1.3 -> 0 | S35: 4 | T35: =(P35*5900+Q35*3400+S35*300)/O35 -> 1500 | U35: 1500 | V35: 10 | W35: 0.5 | X35: =(AB35*V35-W35*5900-Z35*300)/3400 -> 4.0294118 | Y35: =R35*1.2 -> 0 | Z35: 4.5 | AA35: =(W35*5900+X35*3400+Z35*300)/V35 -> 1800 | AB35: =U35*1.2 -> 1800
A36: 线下礼金 | H36: 线下礼金 | O36: 线下礼金 | V36: 线下礼金
A37: 2小时及以内玩家礼金 | E37: 450 | H37: 2小时及以内玩家礼金 | L37: 450 | O37: 2小时及以内玩家礼金 | S37: 500 | V37: 2小时及以内玩家礼金 | Z37: 500
A38: 每增加0.5小时，礼金+115 | H38: 每增加0.5小时，礼金+115 | O38: 每增加0.5小时，礼金+115 | V38: 每增加0.5小时，礼金+115
A39: 线上礼金 | H39: 线上礼金 | O39: 线上礼金 | V39: 线上礼金
A40: 2小时及以内玩家礼金 | E40: 350 | H40: 2小时及以内玩家礼金 | L40: 350 | O40: 2小时及以内玩家礼金 | S40: 350 | V40: 2小时及以内玩家礼金 | Z40: 350
A41: 每增加0.5小时，礼金+90 | H41: 每增加0.5小时，礼金+90 | O41: 每增加0.5小时，礼金+90 | V41: 每增加0.5小时，礼金+90

Sheet 24&25年渠道人力对比
A1: 招募 2H以内：2H以上的系数=0.8 国内常规用户难度递增系数：1.2 线上：线下系数=0.8 常规用户-特殊用户难度递增系数=1.64
A2: 国内线下 | B2: 变量范围 | C2: 上半年 | D2: 下半年 | E2: P3单独执行 | F2: 25年预计定价 | G2: 25年实际定价 | H2: 市场价 | L2: 国内线上 | M2: 变量范围 | N2: 24年实际人力 | O2: P3单独执行 | P2: 24年实际人力 线上访谈 | Q2: 24年实际人力 线上测试 | R2: 25年实际定价 | S2: 市场价
A4: 常规一级 | L4: 常规一级
B5: 2H以内 | G5: =G6*0.8 -> 308.8 | H5: 725 | M5: 2H以内 | R5: =G5*0.8 -> 247.04
B6: 2H以上 | G6: 386 | H6: 725 | M6: 2H以上 | R6: =G6*0.8 -> 308.8
A7: 常规二级 | L7: 常规二级
B8: 2H以内 | C8: 263 | F8: 300 | G8: =G9*0.8 -> 349.6 | H8: 900 | M8: 2H以内 | N8: 283 | P8: 227 | Q8: 507 | R8: =G8*0.8 -> 279.68
B9: 2H以上 | C9: 394 | F9: 450 | G9: 437 | H9: 900 | M9: 2H以上 | R9: =G9*0.8 -> 349.6
A10: 常规三级 | L10: 常规三级
B11: 2H以内 | C11: 349 | D11: 280 | E11: 379 | F11: 400 | G11: =G12*0.8 -> 443.12 | H11: 1100 | M11: 2H以内 | N11: 274 | P11: 283 | Q11: 155 | R11: =G11*0.8 -> 354.496
B12: 2H以上 | C12: 400 | D12: 400 | E12: 467 | F12: 550 | G12: 553.9 | H12: 1100 | M12: 2H以上 | N12: 448 | P12: 178 | Q12: 519 | R12: =G12*0.8 -> 443.12
A13: 常规四级 | L13: 常规四级
B14: 2H以内 | C14: 500 | D14: 561 | E14: 846 | G14: =G15*0.8 -> 508 | H14: 1500 | M14: 2H以内 | N14: 268 | O14: 390 | P14: 269 | Q14: 256 | R14: =G14*0.8 -> 406.4
B15: 2H以上 | C15: 524 | D15: 455 | E15: 400 | F15: =F12*1.2 -> 660 | G15: 635 | H15: 1500 | M15: 2H以上 | N15: 217 | O15: 235 | Q15: 217 | R15: =G15*0.8 -> 508
A16: 常规五级 | L16: 常规五级
B17: 2H以内 | C17: 494 | G17: =G18*0.8 -> 544 | H17: 1500 | M17: 2H以内 | N17: 423 | P17: 423 | R17: =G17*0.8 -> 435.2
B18: 2H以上 | C18: 681 | E18: 566 | G18: 680 | H18: 1500 | M18: 2H以上 | N18: 212 | Q18: 212 | R18: =G18*0.8 -> 544
A19: 特殊-一级 | L19: 特殊-一级
B20: 2H以内 | G20: 650 | M20: 2H以内 | R20: =G20 -> 650
B21: 2H以上 | G21: 650 | M21: 2H以上 | R21: =G21 -> 650
A22: 特殊二级 | L22: 特殊二级
B23: 2H以内 | G23: =AVERAGE(F8:F9)*2 -> 750 | M23: 2H以内 | R23: =G23 -> 750
B24: 2H以上 | G24: 750 | M24: 2H以上 | R24: =G24 -> 750
A25: 特殊三级 | L25: 特殊三级
B26: 2H以内 | G26: 950 | M26: 2H以内 | N26: 1053 | R26: =G26 -> 950
B27: 2H以上 | C27: 2060 | G27: 950 | M27: 2H以上 | R27: =G27 -> 950
A28: 特殊-四级 | L28: 特殊-四级
B29: 2H以内 | C29: 1366 | D29: 1366 | G29: 1000 | M29: 2H以内 | N29: 1769 | R29: =G29 -> 1000
B30: 2H以上 | C30: 1150 | G30: 1000 | M30: 2H以上 | R30: =G30 -> 1000
A31: 小众-一级 | L31: 小众-一级
B32: 2H以内 | G32: 1200 | H32: 2000 | M32: 2H以内 | R32: =G32 -> 1200 | S32: 2000
B33: 2H以上 | G33: 1200 | H33: 2000 | M33: 2H以上 | R33: =G33 -> 1200 | S33: 2000
A34: 小众-二级 | L34: 小众-二级
B35: 2H以内 | G35: 1400 | H35: 2000 | M35: 2H以内 | R35: =G35 -> 1400 | S35: 2000
B36: 2H以上 | G36: 1400 | H36: 2000 | M36: 2H以上 | R36: =G36 -> 1400 | S36: 2000
A37: 小众-三级 | L37: 小众-三级
B38: 2H以内 | C38: 387 | G38: 1500 | H38: 2000 | M38: 2H以内 | N38: 2752 | R38: =G38 -> 1500 | S38: 2000
B39: 2H以上 | C39: 679 | G39: 1500 | H39: 2000 | M39: 2H以上 | R39: =G39 -> 1500 | S39: 2000
A40: 小众-四级 | L40: 小众-四级
B41: 2H以内 | G41: 1600 | H41: 2000 | M41: 2H以内 | R41: =G41 -> 1600 | S41: 2000
...

Sheet 【国内】问卷调研-数据源（P3单独执行） 
B1: 人群难度 | C1: 一级难度 | J1: 人群难度 | L1: 一级难度 | R1: 人群难度 | T1: 一级难度 | Z1: 人群难度 | AB1: 一级难度 | AH1: 人群难度 | AJ1: 一级难度 | AP1: 人群难度 | AR1: 一级难度 | AX1: 人群难度 | AZ1: 一级难度
B2: 问卷难度 | C2: 20题以内 | J2: 问卷难度 | L2: 21~30题 | R2: 问卷难度 | T2: 31~40题 | Z2: 问卷难度 | AB2: 41~50题 | AH2: 问卷难度 | AJ2: 51~60 | AP2: 问卷难度 | AR2: 61~70 | AX2: 问卷难度 | AZ2: 71~80
B3: 单价 | D3: 2 | G3: =AVERAGE(G7:G22) -> 8.0302204 | J3: 单价 | L3: 3 | O3: =AVERAGE(O6:O22) -> 9.2972786 | R3: 单价 | T3: 4 | W3: =AVERAGE(W6:W22) -> 10.919056 | Z3: 单价 | AB3: 5 | AE3: =AVERAGE(AE7:AE22) -> 12.801738 | AH3: 单价 | AJ3: 6 | AM3: =AVERAGE(AM7:AM22) -> 14.462377 | AP3: 单价 | AR3: 7 | AU3: =AVERAGE(AU7:AU22) -> 16.123015 | AX3: 单价 | AZ3: 8 | BC3: =AVERAGE(BC7:BC22) -> 17.783653 | BE3: =AVERAGE(BC3,AU3,AM3,AE3,W3,O3,G3) -> 12.773905 | BF3: =BE3-AVERAGE(AZ3,AR3,AJ3,AB3,T3,L3,D3) -> 7.7739052
B4: 份数 | C4: P5 | D4: P4 | E4: P3 | F4: 实习生 | G4: 成本 | H4: 上限 | J4: 份数 | K4: P5 | L4: P4 | M4: P3 | N4: 实习生 | O4: 成本 | P4: 上限 | R4: 份数 | S4: P5 | T4: P4 | U4: P3 | V4: 实习生 | W4: 成本 | X4: 上限 | Z4: 份数 | AA4: P5 | AB4: P4 | AC4: P3 | AD4: 实习生 | AE4: 成本 | AF4: 上限 | AH4: 份数 | AI4: P5 | AJ4: P4 | AK4: P3 | AL4: 实习生 | AM4: 成本 | AP4: 份数 | AQ4: P5 | AR4: P4 | AS4: P3 | AT4: 实习生 | AX4: 份数 | AY4: P5 | AZ4: P4 | BA4: P3 | BB4: 实习生
B5: 0 | C5: =S5 -> 0 | D5: 0 | F5: 0 | G5: =(C5*5900+E5*3400+F5*300+B5*$D$3)/B5 -> #DIV/0! | H5: 18 | J5: 0 | K5: =C5 -> 0 | L5: 0 | M5: 0 | N5: 0 | O5: =(K5*5900+M5*3400+N5*300+J5*$L$3)/J5 -> #DIV/0! | P5: 18 | R5: 0 | S5: 0 | T5: 0 | U5: 0 | V5: 0 | W5: =(S5*5900+U5*3400+V5*300+R5*$T$3)/R5 -> #DIV/0! | X5: 18 | Z5: 0 | AA5: =S5 -> 0 | AB5: 0 | AC5: 0 | AD5: 0 | AE5: =(AA5*5900+AC5*3400+AD5*300+Z5*$AB$3)/Z5 -> #DIV/0! | AH5: 0 | AI5: =AA5 -> 0 | AJ5: 0 | AK5: 0 | AL5: 0 | AM5: =(AI5*5900+AK5*3400+AL5*300+AH5*$AJ$3)/AH5 -> #DIV/0! | AP5: 0 | AQ5: =AI5 -> 0 | AR5: 0 | AS5: 0 | AT5: 0 | AU5: =(AQ5*5900+AS5*3400+AT5*300+AP5*$AR$3)/AP5 -> #DIV/0! | AX5: 0 | AY5: =AQ5 -> 0 | AZ5: 0 | BA5: 0 | BB5: 0 | BC5: =(AY5*5900+BA5*3400+BB5*300+AX5*$AZ$3)/AX5 -> #DIV/0!
A6: 100份及以下 | B6: 1 | C6: 0 | D6: =D7 -> 0 | E6: 0 | F6: 0 | G6: =(C6*5900+E6*3400+F6*300+$D$3*B6)/B6 -> 2 | H6: 18 | J6: 1 | K6: 0 | L6: =L7 -> 0 | M6: 0 | N6: 0 | O6: =(K6*5900+M6*3400+N6*300+$L$3*J6)/J6 -> 3 | P6: 18 | R6: 1 | S6: =S7 -> 0 | T6: =T7 -> 0 | U6: 0 | V6: 0 | W6: =(S6*5900+U6*3400+V6*300+$T$3*R6)/R6 -> 4 | X6: 18 | Z6: 1 | AA6: =AA7 -> 0 | AB6: =AB7 -> 0 | AC6: =AC7 -> 0.5 | AD6: =AD7 -> 1.2 | AE6: =(AA6*5900+AC6*3400+AD6*300)/Z6 -> 2060 | AH6: 1 | AI6: =AI7 -> 0 | AJ6: =AJ7 -> 0 | AK6: =AK7 -> 0.6 | AL6: =AL7 -> 1.3 | AM6: =(AI6*5900+AK6*3400+AL6*300+$AJ$3*AH6)/AH6 -> 2436 | AP6: 1 | AQ6: =AQ7 -> 0 | AR6: =AR7 -> 0 | AS6: =AS7 -> 0.7 | AT6: =AT7 -> 1.4 | AU6: =(AQ6*5900+AS6*3400+AT6*300)/AP6 -> 2800 | AX6: 1 | AY6: =AY7 -> 0 | AZ6: =AZ7 -> 0 | BA6: =BA7 -> 0.8 | BB6: =BB7 -> 1.5 | BC6: =(AY6*5900+BA6*3400+BB6*300+$AZ$3*AX6)/AX6 -> 3178
A7: 101~200份 | B7: 101 | C7: =S7 -> 0 | D7: 0 | E7: =E30-0.1 -> 0.3 | F7: =N7-0.1 -> 0.9 | G7: =(C7*5900+E7*3400+F7*300+$D$3*B7)/B7 -> 14.772277 | H7: 18 | J7: 101 | K7: =C7 -> 0 | L7: 0 | M7: =E7+0.1 -> 0.4 | N7: 1 | O7: =(K7*5900+M7*3400+N7*300+$L$3*J7)/J7 -> 19.435644 | P7: 18 | R7: 101 | S7: 0 | T7: 0 | U7: =M7+0.1 -> 0.5 | V7: =N7+0.1 -> 1.1 | W7: =(S7*5900+U7*3400+V7*300+$T$3*R7)/R7 -> 24.09901 | X7: 18 | Z7: 101 | AA7: =S7 -> 0 | AB7: 0 | AC7: 0.5 | AD7: =V7+0.1 -> 1.2 | AE7: =(AA7*5900+AC7*3400+AD7*300+$AB$3*Z7)/Z7 -> 25.39604 | AH7: 101 | AI7: =AA7 -> 0 | AJ7: 0 | AK7: =AC7+0.1 -> 0.6 | AL7: =AD7+0.1 -> 1.3 | AM7: =(AI7*5900+AK7*3400+AL7*300+$AJ$3*AH7)/AH7 -> 30.059406 | AP7: 101 | AQ7: =AI7 -> 0 | AR7: 0 | AS7: =AK7+0.1 -> 0.7 | AT7: =AL7+0.1 -> 1.4 | AU7: =(AQ7*5900+AS7*3400+AT7*300+AP7*$AR$3)/AP7 -> 34.722772 | AX7: 101 | AY7: =AQ7 -> 0 | AZ7: 0 | BA7: =AS7+0.1 -> 0.8 | BB7: =AT7+0.1 -> 1.5 | BC7: =(AY7*5900+BA7*3400+BB7*300+$AZ$3*AX7)/AX7 -> 39.386139
A8: 201~300份 | B8: 201 | C8: =S8 -> 0 | D8: 0 | E8: 0.4 | F8: =N8-0.1 -> 0.9 | G8: =(C8*5900+E8*3400+F8*300+$D$3*B8)/B8 -> 10.109453 | H8: 18 | J8: 201 | K8: =C8 -> 0 | L8: 0 | M8: =E8+0.1 -> 0.5 | N8: 1 | O8: =(K8*5900+M8*3400+N8*300+$L$3*J8)/J8 -> 12.950249 | P8: 18 | R8: 201 | S8: 0 | T8: 0 | U8: =M8+0.1 -> 0.6 | V8: =N8+0.1 -> 1.1 | W8: =(S8*5900+U8*3400+V8*300+$T$3*R8)/R8 -> 15.791045 | X8: 18 | Z8: 201 | AA8: =S8 -> 0 | AB8: 0 | AC8: =U8+0.1 -> 0.7 | AD8: =V8+0.1 -> 1.2 | AE8: =(AA8*5900+AC8*3400+AD8*300+$AB$3*Z8)/Z8 -> 18.631841 | AH8: 201 | AI8: =AA8 -> 0 | AJ8: 0 | AK8: =AC8+0.1 -> 0.8 | AL8: =AD8+0.1 -> 1.3 | AM8: =(AI8*5900+AK8*3400+AL8*300+$AJ$3*AH8)/AH8 -> 21.472637 | AP8: 201 | AQ8: =AI8 -> 0 | AR8: 0 | AS8: =AK8+0.1 -> 0.9 | AT8: =AL8+0.1 -> 1.4 | AU8: =(AQ8*5900+AS8*3400+AT8*300+AP8*$AR$3)/AP8 -> 24.313433 | AX8: 201 | AY8: =AQ8 -> 0 | AZ8: 0 | BA8: =AS8+0.1 -> 1 | BB8: =AT8+0.1 -> 1.5 | BC8: =(AY8*5900+BA8*3400+BB8*300+$AZ$3*AX8)/AX8 -> 27.154229
A9: 301~500份 | B9: 301 | C9: =S9 -> 0 | D9: 0.2 | E9: 0.5 | F9: =N9-0.1 -> 0.9 | G9: =(C9*5900+E9*3400+F9*300+$D$3*B9)/B9 -> 8.5448505 | H9: 18 | J9: 301 | K9: =C9 -> 0 | L9: 0.2 | M9: =E9+0.1 -> 0.6 | N9: 1 | O9: =(K9*5900+M9*3400+N9*300+$L$3*J9)/J9 -> 10.774086 | P9: 18 | R9: 301 | S9: 0 | T9: 0.2 | U9: =M9+0.1 -> 0.7 | V9: =N9+0.1 -> 1.1 | W9: =(S9*5900+U9*3400+V9*300+$T$3*R9)/R9 -> 13.003322 | X9: 18 | Z9: 301 | AA9: =S9 -> 0 | AB9: 0.2 | AC9: =U9+0.1 -> 0.8 | AD9: =V9+0.1 -> 1.2 | AE9: =(AA9*5900+AC9*3400+AD9*300+$AB$3*Z9)/Z9 -> 15.232558 | AH9: 301 | AI9: =AA9 -> 0 | AJ9: 0.2 | AK9: =AC9+0.1 -> 0.9 | AL9: =AD9+0.1 -> 1.3 | AM9: =(AI9*5900+AK9*3400+AL9*300+$AJ$3*AH9)/AH9 -> 17.461794 | AP9: 301 | AQ9: =AI9 -> 0 | AR9: 0.2 | AS9: =AK9+0.1 -> 1 | AT9: =AL9+0.1 -> 1.4 | AU9: =(AQ9*5900+AS9*3400+AT9*300+AP9*$AR$3)/AP9 -> 19.69103 | AX9: 301 | AY9: =AQ9 -> 0 | AZ9: 0.2 | BA9: =AS9+0.1 -> 1.1 | BB9: =AT9+0.1 -> 1.5 | BC9: =(AY9*5900+BA9*3400+BB9*300+$AZ$3*AX9)/AX9 -> 21.920266
A10: 501~700份 | B10: 501 | C10: =S10 -> 0 | D10: 0.2 | E10: 0.9 | F10: =N10-0.1 -> 0.9 | G10: =(C10*5900+E10*3400+F10*300+$D$3*B10)/B10 -> 8.6467066 | H10: 18 | J10: 501 | K10: =C10 -> 0 | L10: 0.2 | M10: =E10+0.1 -> 1 | N10: 1 | O10: =(K10*5900+M10*3400+N10*300+$L$3*J10)/J10 -> 10.38523 | P10: 18 | R10: 501 | S10: 0 | T10: 0.2 | U10: =M10+0.1 -> 1.1 | V10: =N10+0.1 -> 1.1 | W10: =(S10*5900+U10*3400+V10*300+$T$3*R10)/R10 -> 12.123752 | X10: 18 | Z10: 501 | AA10: =S10 -> 0 | AB10: 0.2 | AC10: =U10+0.1 -> 1.2 | AD10: =V10+0.1 -> 1.2 | AE10: =(AA10*5900+AC10*3400+AD10*300+$AB$3*Z10)/Z10 -> 13.862275 | AH10: 501 | AI10: =AA10 -> 0 | AJ10: 0.2 | AK10: =AC10+0.1 -> 1.3 | AL10: =AD10+0.1 -> 1.3 | AM10: =(AI10*5900+AK10*3400+AL10*300+$AJ$3*AH10)/AH10 -> 15.600798 | AP10: 501 | AQ10: =AI10 -> 0 | AR10: 0.2 | AS10: =AK10+0.1 -> 1.4 | AT10: =AL10+0.1 -> 1.4 | AU10: =(AQ10*5900+AS10*3400+AT10*300+AP10*$AR$3)/AP10 -> 17.339321 | AX10: 501 | AY10: =AQ10 -> 0 | AZ10: 0.2 | BA10: =AS10+0.1 -> 1.5 | BB10: =AT10+0.1 -> 1.5 | BC10: =(AY10*5900+BA10*3400+BB10*300+$AZ$3*AX10)/AX10 -> 19.077844
A11: 701~900份 | B11: 701 | C11: =S11 -> 0 | D11: 0.2 | E11: 1.1 | F11: =N11-0.1 -> 0.9 | G11: =(C11*5900+E11*3400+F11*300+$D$3*B11)/B11 -> 7.7203994 | H11: 18 | J11: 701 | K11: =C11 -> 0 | L11: 0.2 | M11: =E11+0.1 -> 1.2 | N11: 1 | O11: =(K11*5900+M11*3400+N11*300+$L$3*J11)/J11 -> 9.2482168 | P11: 18 | R11: 701 | S11: 0 | T11: 0.2 | U11: =M11+0.1 -> 1.3 | V11: =N11+0.1 -> 1.1 | W11: =(S11*5900+U11*3400+V11*300+$T$3*R11)/R11 -> 10.776034 | X11: 18 | Z11: 701 | AA11: =S11 -> 0 | AB11: 0.2 | AC11: =U11+0.1 -> 1.4 | AD11: =V11+0.1 -> 1.2 | AE11: =(AA11*5900+AC11*3400+AD11*300+$AB$3*Z11)/Z11 -> 12.303852 | AH11: 701 | AI11: =AA11 -> 0 | AJ11: 0.2 | AK11: =AC11+0.1 -> 1.5 | AL11: =AD11+0.1 -> 1.3 | AM11: =(AI11*5900+AK11*3400+AL11*300+$AJ$3*AH11)/AH11 -> 13.831669 | AP11: 701 | AQ11: =AI11 -> 0 | AR11: 0.2 | AS11: =AK11+0.1 -> 1.6 | AT11: =AL11+0.1 -> 1.4 | AU11: =(AQ11*5900+AS11*3400+AT11*300+AP11*$AR$3)/AP11 -> 15.359486 | AX11: 701 | AY11: =AQ11 -> 0 | AZ11: 0.2 | BA11: =AS11+0.1 -> 1.7 | BB11: =AT11+0.1 -> 1.5 | BC11: =(AY11*5900+BA11*3400+BB11*300+$AZ$3*AX11)/AX11 -> 16.887304
A12: 901~1000份 | B12: 901 | C12: =S12 -> 0 | D12: 0.3 | E12: 1.5 | F12: =N12-0.1 -> 0.9 | G12: =(C12*5900+E12*3400+F12*300+$D$3*B12)/B12 -> 7.9600444 | H12: 18 | J12: 901 | K12: =C12 -> 0 | L12: 0.3 | M12: =E12+0.1 -> 1.6 | N12: 1 | O12: =(K12*5900+M12*3400+N12*300+$L$3*J12)/J12 -> 9.3706992 | P12: 18 | R12: 901 | S12: 0 | T12: 0.3 | U12: =M12+0.1 -> 1.7 | V12: =N12+0.1 -> 1.1 | W12: =(S12*5900+U12*3400+V12*300+$T$3*R12)/R12 -> 10.781354 | X12: 18 | Z12: 901 | AA12: =S12 -> 0 | AB12: 0.3 | AC12: =U12+0.1 -> 1.8 | AD12: =V12+0.1 -> 1.2 | AE12: =(AA12*5900+AC12*3400+AD12*300+$AB$3*Z12)/Z12 -> 12.192009 | AH12: 901 | AI12: =AA12 -> 0 | AJ12: 0.3 | AK12: =AC12+0.1 -> 1.9 | AL12: =AD12+0.1 -> 1.3 | AM12: =(AI12*5900+AK12*3400+AL12*300+$AJ$3*AH12)/AH12 -> 13.602664 | AP12: 901 | AQ12: =AI12 -> 0 | AR12: 0.3 | AS12: =AK12+0.1 -> 2 | AT12: =AL12+0.1 -> 1.4 | AU12: =(AQ12*5900+AS12*3400+AT12*300+AP12*$AR$3)/AP12 -> 15.013319 | AX12: 901 | AY12: =AQ12 -> 0 | AZ12: 0.3 | BA12: =AS12+0.1 -> 2.1 | BB12: =AT12+0.1 -> 1.5 | BC12: =(AY12*5900+BA12*3400+BB12*300+$AZ$3*AX12)/AX12 -> 16.423973
A13: 1001~1200份 | B13: 1001 | C13: =S13 -> 0 | D13: 0.4 | E13: =E36-0.1 -> 1.8 | F13: =N13-0.1 -> 1.9 | G13: =(C13*5900+E13*3400+F13*300+$D$3*B13)/B13 -> 8.6833167 | H13: 18 | J13: 1001 | K13: =C13 -> 0 | L13: 0.4 | M13: =E13+0.1 -> 1.9 | N13: 2 | O13: =(K13*5900+M13*3400+N13*300+$L$3*J13)/J13 -> 10.052947 | P13: 18 | R13: 1001 | S13: =S36-0.1 -> 0 | T13: 0.4 | U13: =M13+0.1 -> 2 | V13: =N13+0.1 -> 2.1 | W13: =(S13*5900+U13*3400+V13*300+$T$3*R13)/R13 -> 11.422577 | X13: 18 | Z13: 1001 | AA13: =S13 -> 0 | AB13: 0.4 | AC13: =U13+0.1 -> 2.1 | AD13: =V13+0.1 -> 2.2 | AE13: =(AA13*5900+AC13*3400+AD13*300+$AB$3*Z13)/Z13 -> 12.792208 | AH13: 1001 | AI13: =AA13 -> 0 | AJ13: 0.4 | AK13: =AC13+0.1 -> 2.2 | AL13: =AD13+0.1 -> 2.3 | AM13: =(AI13*5900+AK13*3400+AL13*300+$AJ$3*AH13)/AH13 -> 14.161838 | AP13: 1001 | AQ13: =AI13 -> 0 | AR13: 0.4 | AS13: =AK13+0.1 -> 2.3 | AT13: =AL13+0.1 -> 2.4 | AU13: =(AQ13*5900+AS13*3400+AT13*300+AP13*$AR$3)/AP13 -> 15.531469 | AX13: 1001 | AY13: =AQ13 -> 0 | AZ13: 0.4 | BA13: =AS13+0.1 -> 2.4 | BB13: =AT13+0.1 -> 2.5 | BC13: =(AY13*5900+BA13*3400+BB13*300+$AZ$3*AX13)/AX13 -> 16.901099
A14: 1201~1400份 | B14: 1201 | C14: =S14 -> 0 | D14: 0.5 | E14: =E37-0.1 -> 1.9 | F14: =N14-0.1 -> 1.9 | G14: =(C14*5900+E14*3400+F14*300+$D$3*B14)/B14 -> 7.8534555 | H14: 18 | J14: 1201 | K14: =C14 -> 0 | L14: 0.5 | M14: =E14+0.1 -> 2 | N14: 2 | O14: =(K14*5900+M14*3400+N14*300+$L$3*J14)/J14 -> 9.1615321 | P14: 18 | R14: 1201 | S14: =S37-0.1 -> 0 | T14: 0.5 | U14: =M14+0.1 -> 2.1 | V14: =N14+0.1 -> 2.1 | W14: =(S14*5900+U14*3400+V14*300+$T$3*R14)/R14 -> 10.469609 | X14: 18 | Z14: 1201 | AA14: =S14 -> 0 | AB14: 0.5 | AC14: =U14+0.1 -> 2.2 | AD14: =V14+0.1 -> 2.2 | AE14: =(AA14*5900+AC14*3400+AD14*300+$AB$3*Z14)/Z14 -> 11.777685 | AH14: 1201 | AI14: =AA14 -> 0 | AJ14: 0.5 | AK14: =AC14+0.1 -> 2.3 | AL14: =AD14+0.1 -> 2.3 | AM14: =(AI14*5900+AK14*3400+AL14*300+$AJ$3*AH14)/AH14 -> 13.085762 | AP14: 1201 | AQ14: =AI14 -> 0 | AR14: 0.5 | AS14: =AK14+0.1 -> 2.4 | AT14: =AL14+0.1 -> 2.4 | AU14: =(AQ14*5900+AS14*3400+AT14*300+AP14*$AR$3)/AP14 -> 14.393838 | AX14: 1201 | AY14: =AQ14 -> 0 | AZ14: 0.5 | BA14: =AS14+0.1 -> 2.5 | BB14: =AT14+0.1 -> 2.5 | BC14: =(AY14*5900+BA14*3400+BB14*300+$AZ$3*AX14)/AX14 -> 15.701915
A15: 1401~1600份 | B15: 1401 | C15: =S15 -> 0 | D15: 0.5 | E15: =E38-0.1 -> 2 | F15: =N15-0.1 -> 1.9 | G15: =(C15*5900+E15*3400+F15*300+$D$3*B15)/B15 -> 7.2605282 | H15: 18 | J15: 1401 | K15: =C15 -> 0 | L15: 0.5 | M15: =E15+0.1 -> 2.1 | N15: 2 | O15: =(K15*5900+M15*3400+N15*300+$L$3*J15)/J15 -> 8.5246253 | P15: 18 | R15: 1401 | S15: =S38-0.1 -> 0 | T15: 0.5 | U15: =M15+0.1 -> 2.2 | V15: =N15+0.1 -> 2.1 | W15: =(S15*5900+U15*3400+V15*300+$T$3*R15)/R15 -> 9.7887223 | X15: 18 | Z15: 1401 | AA15: =S15 -> 0 | AB15: 0.5 | AC15: =U15+0.1 -> 2.3 | AD15: =V15+0.1 -> 2.2 | AE15: =(AA15*5900+AC15*3400+AD15*300+$AB$3*Z15)/Z15 -> 11.052819 | AH15: 1401 | AI15: =AA15 -> 0 | AJ15: 0.5 | AK15: =AC15+0.1 -> 2.4 | AL15: =AD15+0.1 -> 2.3 | AM15: =(AI15*5900+AK15*3400+AL15*300+$AJ$3*AH15)/AH15 -> 12.316916 | AP15: 1401 | AQ15: =AI15 -> 0 | AR15: 0.5 | AS15: =AK15+0.1 -> 2.5 | AT15: =AL15+0.1 -> 2.4 | AU15: =(AQ15*5900+AS15*3400+AT15*300+AP15*$AR$3)/AP15 -> 13.581014 | AX15: 1401 | AY15: =AQ15 -> 0 | AZ15: 0.5 | BA15: =AS15+0.1 -> 2.6 | BB15: =AT15+0.1 -> 2.5 | BC15: =(AY15*5900+BA15*3400+BB15*300+$AZ$3*AX15)/AX15 -> 14.845111
A16: 1601~1800份 | B16: 1601 | C16: =S16 -> 0 | D16: 0.6 | E16: =E39-0.1 -> 2.2 | F16: =N16-0.1 -> 1.9 | G16: =(C16*5900+E16*3400+F16*300+$D$3*B16)/B16 -> 7.0281074 | H16: 18 | J16: 1601 | K16: =C16 -> 0 | L16: 0.6 | M16: =E16+0.1 -> 2.3 | N16: 2 | O16: =(K16*5900+M16*3400+N16*300+$L$3*J16)/J16 -> 8.259213 | P16: 18 | R16: 1601 | S16: =S39-0.1 -> 0 | T16: 0.6 | U16: =M16+0.1 -> 2.4 | V16: =N16+0.1 -> 2.1 | W16: =(S16*5900+U16*3400+V16*300+$T$3*R16)/R16 -> 9.4903186 | X16: 18 | Z16: 1601 | AA16: =S16 -> 0 | AB16: 0.6 | AC16: =U16+0.1 -> 2.5 | AD16: =V16+0.1 -> 2.2 | AE16: =(AA16*5900+AC16*3400+AD16*300+$AB$3*Z16)/Z16 -> 10.721424 | AH16: 1601 | AI16: =AA16 -> 0 | AJ16: 0.6 | AK16: =AC16+0.1 -> 2.6 | AL16: =AD16+0.1 -> 2.3 | AM16: =(AI16*5900+AK16*3400+AL16*300+$AJ$3*AH16)/AH16 -> 11.95253 | AP16: 1601 | AQ16: =AI16 -> 0 | AR16: 0.6 | AS16: =AK16+0.1 -> 2.7 | AT16: =AL16+0.1 -> 2.4 | AU16: =(AQ16*5900+AS16*3400+AT16*300+AP16*$AR$3)/AP16 -> 13.183635 | AX16: 1601 | AY16: =AQ16 -> 0 | AZ16: 0.6 | BA16: =AS16+0.1 -> 2.8 | BB16: =AT16+0.1 -> 2.5 | BC16: =(AY16*5900+BA16*3400+BB16*300+$AZ$3*AX16)/AX16 -> 14.414741
A17: 1801~2000份 | B17: 1801 | C17: =S17 -> 0 | D17: 0.6 | E17: =E40-0.1 -> 2.4 | F17: =N17-0.1 -> 1.9 | G17: =(C17*5900+E17*3400+F17*300+$D$3*B17)/B17 -> 6.8473071 | H17: 18 | J17: 1801 | K17: =C17 -> 0 | L17: 0.6 | M17: =E17+0.1 -> 2.5 | N17: 2 | O17: =(K17*5900+M17*3400+N17*300+$L$3*J17)/J17 -> 8.0527485 | P17: 18 | R17: 1801 | S17: =S40-0.1 -> 0 | T17: 0.6 | U17: =M17+0.1 -> 2.6 | V17: =N17+0.1 -> 2.1 | W17: =(S17*5900+U17*3400+V17*300+$T$3*R17)/R17 -> 9.2581899 | X17: 18 | Z17: 1801 | AA17: =S17 -> 0 | AB17: 0.6 | AC17: =U17+0.1 -> 2.7 | AD17: =V17+0.1 -> 2.2 | AE17: =(AA17*5900+AC17*3400+AD17*300+$AB$3*Z17)/Z17 -> 10.463631 | AH17: 1801 | AI17: =AA17 -> 0 | AJ17: 0.6 | AK17: =AC17+0.1 -> 2.8 | AL17: =AD17+0.1 -> 2.3 | AM17: =(AI17*5900+AK17*3400+AL17*300+$AJ$3*AH17)/AH17 -> 11.669073 | AP17: 1801 | AQ17: =AI17 -> 0 | AR17: 0.6 | AS17: =AK17+0.1 -> 2.9 | AT17: =AL17+0.1 -> 2.4 | AU17: =(AQ17*5900+AS17*3400+AT17*300+AP17*$AR$3)/AP17 -> 12.874514 | AX17: 1801 | AY17: =AQ17 -> 0 | AZ17: 0.6 | BA17: =AS17+0.1 -> 3 | BB17: =AT17+0.1 -> 2.5 | BC17: =(AY17*5900+BA17*3400+BB17*300+$AZ$3*AX17)/AX17 -> 14.079956
A18: 2001~2200份 | B18: 2001 | C18: =S18 -> 0.1 | D18: 0.7 | E18: 2.5 | F18: =N18-0.1 -> 1.9 | G18: =(C18*5900+E18*3400+F18*300+$D$3*B18)/B18 -> 6.8275862 | H18: 18 | J18: 2001 | K18: =C18 -> 0.1 | L18: 0.7 | M18: =E18+0.1 -> 2.6 | N18: 2 | O18: =(K18*5900+M18*3400+N18*300+$L$3*J18)/J18 -> 8.0124938 | P18: 18 | R18: 2001 | S18: =S41-0.1 -> 0.1 | T18: 0.7 | U18: =M18+0.1 -> 2.7 | V18: =N18+0.1 -> 2.1 | W18: =(S18*5900+U18*3400+V18*300+$T$3*R18)/R18 -> 9.1974013 | X18: 18 | Z18: 2001 | AA18: =S18 -> 0.1 | AB18: 0.7 | AC18: =U18+0.1 -> 2.8 | AD18: =V18+0.1 -> 2.2 | AE18: =(AA18*5900+AC18*3400+AD18*300+$AB$3*Z18)/Z18 -> 10.382309 | AH18: 2001 | AI18: =AA18 -> 0.1 | AJ18: 0.7 | AK18: =AC18+0.1 -> 2.9 | AL18: =AD18+0.1 -> 2.3 | AM18: =(AI18*5900+AK18*3400+AL18*300+$AJ$3*AH18)/AH18 -> 11.567216 | AP18: 2001 | AQ18: =AI18 -> 0.1 | AR18: 0.7 | AS18: =AK18+0.1 -> 3 | AT18: =AL18+0.1 -> 2.4 | AU18: =(AQ18*5900+AS18*3400+AT18*300+AP18*$AR$3)/AP18 -> 12.752124 | AX18: 2001 | AY18: =AQ18 -> 0.1 | AZ18: 0.7 | BA18: =AS18+0.1 -> 3.1 | BB18: =AT18+0.1 -> 2.5 | BC18: =(AY18*5900+BA18*3400+BB18*300+$AZ$3*AX18)/AX18 -> 13.937031
A19: 2201~2400份 | B19: 2201 | C19: =S19 -> 0.1 | D19: 0.7 | E19: =E42-0.1 -> 2.8 | F19: =N19-0.1 -> 1.9 | G19: =(C19*5900+E19*3400+F19*300+$D$3*B19)/B19 -> 6.8523398 | H19: 18 | J19: 2201 | K19: =C19 -> 0.1 | L19: 0.7 | M19: =E19+0.1 -> 2.9 | N19: 2 | O19: =(K19*5900+M19*3400+N19*300+$L$3*J19)/J19 -> 8.0204453 | P19: 18 | R19: 2201 | S19: =S42-0.1 -> 0.1 | T19: 0.7 | U19: =M19+0.1 -> 3 | V19: =N19+0.1 -> 2.1 | W19: =(S19*5900+U19*3400+V19*300+$T$3*R19)/R19 -> 9.1885507 | X19: 18 | Z19: 2201 | AA19: =S19 -> 0.1 | AB19: 0.7 | AC19: =U19+0.1 -> 3.1 | AD19: =V19+0.1 -> 2.2 | AE19: =(AA19*5900+AC19*3400+AD19*300+$AB$3*Z19)/Z19 -> 10.356656 | AH19: 2201 | AI19: =AA19 -> 0.1 | AJ19: 0.7 | AK19: =AC19+0.1 -> 3.2 | AL19: =AD19+0.1 -> 2.3 | AM19: =(AI19*5900+AK19*3400+AL19*300+$AJ$3*AH19)/AH19 -> 11.524761 | AP19: 2201 | AQ19: =AI19 -> 0.1 | AR19: 0.7 | AS19: =AK19+0.1 -> 3.3 | AT19: =AL19+0.1 -> 2.4 | AU19: =(AQ19*5900+AS19*3400+AT19*300+AP19*$AR$3)/AP19 -> 12.692867 | AX19: 2201 | AY19: =AQ19 -> 0.1 | AZ19: 0.7 | BA19: =AS19+0.1 -> 3.4 | BB19: =AT19+0.1 -> 2.5 | BC19: =(AY19*5900+BA19*3400+BB19*300+$AZ$3*AX19)/AX19 -> 13.860972
A20: 2401~2600份 | B20: 2401 | C20: =S20 -> 0.1 | D20: 0.8 | E20: =E43-0.1 -> 2.9 | F20: =N20-0.1 -> 1.9 | G20: =(C20*5900+E20*3400+F20*300+$D$3*B20)/B20 -> 6.5897543 | H20: 18 | J20: 2401 | K20: =C20 -> 0.1 | L20: 0.8 | M20: =E20+0.1 -> 3 | N20: 2 | O20: =(K20*5900+M20*3400+N20*300+$L$3*J20)/J20 -> 7.7438567 | P20: 18 | R20: 2401 | S20: =S43-0.1 -> 0.1 | T20: 0.8 | U20: =M20+0.1 -> 3.1 | V20: =N20+0.1 -> 2.1 | W20: =(S20*5900+U20*3400+V20*300+$T$3*R20)/R20 -> 8.8979592 | X20: 18 | Z20: 2401 | AA20: =S20 -> 0.1 | AB20: 0.8 | AC20: =U20+0.1 -> 3.2 | AD20: =V20+0.1 -> 2.2 | AE20: =(AA20*5900+AC20*3400+AD20*300+$AB$3*Z20)/Z20 -> 10.052062 | AH20: 2401 | AI20: =AA20 -> 0.1 | AJ20: 0.8 | AK20: =AC20+0.1 -> 3.3 | AL20: =AD20+0.1 -> 2.3 | AM20: =(AI20*5900+AK20*3400+AL20*300+$AJ$3*AH20)/AH20 -> 11.206164 | AP20: 2401 | AQ20: =AI20 -> 0.1 | AR20: 0.8 | AS20: =AK20+0.1 -> 3.4 | AT20: =AL20+0.1 -> 2.4 | AU20: =(AQ20*5900+AS20*3400+AT20*300+AP20*$AR$3)/AP20 -> 12.360267 | AX20: 2401 | AY20: =AQ20 -> 0.1 | AZ20: 0.8 | BA20: =AS20+0.1 -> 3.5 | BB20: =AT20+0.1 -> 2.5 | BC20: =(AY20*5900+BA20*3400+BB20*300+$AZ$3*AX20)/AX20 -> 13.514369
A21: 2601~2800份 | B21: 2601 | C21: =S21 -> 0.1 | D21: 0.8 | E21: =E44-0.1 -> 3 | F21: =N21-0.1 -> 1.9 | G21: =(C21*5900+E21*3400+F21*300+$D$3*B21)/B21 -> 6.3675509 | H21: 18 | J21: 2601 | K21: =C21 -> 0.1 | L21: 0.8 | M21: =E21+0.1 -> 3.1 | N21: 2 | O21: =(K21*5900+M21*3400+N21*300+$L$3*J21)/J21 -> 7.5098039 | P21: 18 | R21: 2601 | S21: 0.1 | T21: 0.8 | U21: =M21+0.1 -> 3.2 | V21: =N21+0.1 -> 2.1 | W21: =(S21*5900+U21*3400+V21*300+$T$3*R21)/R21 -> 8.6520569 | X21: 18 | Z21: 2601 | AA21: =S21 -> 0.1 | AB21: 0.8 | AC21: =U21+0.1 -> 3.3 | AD21: =V21+0.1 -> 2.2 | AE21: =(AA21*5900+AC21*3400+AD21*300+$AB$3*Z21)/Z21 -> 9.7943099 | AH21: 2601 | AI21: =AA21 -> 0.1 | AJ21: 0.8 | AK21: =AC21+0.1 -> 3.4 | AL21: =AD21+0.1 -> 2.3 | AM21: =(AI21*5900+AK21*3400+AL21*300+$AJ$3*AH21)/AH21 -> 10.936563 | AP21: 2601 | AQ21: =AI21 -> 0.1 | AR21: 0.8 | AS21: =AK21+0.1 -> 3.5 | AT21: =AL21+0.1 -> 2.4 | AU21: =(AQ21*5900+AS21*3400+AT21*300+AP21*$AR$3)/AP21 -> 12.078816 | AX21: 2601 | AY21: =AQ21 -> 0.1 | AZ21: 0.8 | BA21: =AS21+0.1 -> 3.6 | BB21: =AT21+0.1 -> 2.5 | BC21: =(AY21*5900+BA21*3400+BB21*300+$AZ$3*AX21)/AX21 -> 13.221069
A22: 2801~3000份 | B22: 2801 | C22: =S22 -> 0.1 | D22: 0.8 | E22: 3.3 | F22: =N22-0.1 -> 1.9 | G22: =(C22*5900+E22*3400+F22*300+$D$3*B22)/B22 -> 6.4198501 | H22: 18 | J22: 2801 | K22: =C22 -> 0.1 | L22: 0.8 | M22: =E22+0.1 -> 3.4 | N22: 2 | O22: =(K22*5900+M22*3400+N22*300+$L$3*J22)/J22 -> 7.5519457 | P22: 18 | R22: 2801 | S22: 0.1 | T22: 0.8 | U22: =M22+0.1 -> 3.5 | V22: =N22+0.1 -> 2.1 | W22: =(S22*5900+U22*3400+V22*300+$T$3*R22)/R22 -> 8.6840414 | X22: 18 | Z22: 2801 | AA22: =S22 -> 0.1 | AB22: 0.8 | AC22: =U22+0.1 -> 3.6 | AD22: =V22+0.1 -> 2.2 | AE22: =(AA22*5900+AC22*3400+AD22*300+$AB$3*Z22)/Z22 -> 9.8161371 | AH22: 2801 | AI22: =AA22 -> 0.1 | AJ22: 0.8 | AK22: =AC22+0.1 -> 3.7 | AL22: =AD22+0.1 -> 2.3 | AM22: =(AI22*5900+AK22*3400+AL22*300+$AJ$3*AH22)/AH22 -> 10.948233 | AP22: 2801 | AQ22: =AI22 -> 0.1 | AR22: 0.8 | AS22: =AK22+0.1 -> 3.8 | AT22: =AL22+0.1 -> 2.4 | AU22: =(AQ22*5900+AS22*3400+AT22*300+AP22*$AR$3)/AP22 -> 12.080328 | AX22: 2801 | AY22: =AQ22 -> 0.1 | AZ22: 0.8 | BA22: =AS22+0.1 -> 3.9 | BB22: =AT22+0.1 -> 2.5 | BC22: =(AY22*5900+BA22*3400+BB22*300+$AZ$3*AX22)/AX22 -> 13.212424
B24: 人群难度 | C24: 二级难度 | J24: 人群难度 | L24: 二级难度 | R24: 人群难度 | T24: 二级难度 | Z24: 人群难度 | AB24: 二级难度 | AH24: 人群难度 | AJ24: 二级难度 | AP24: 人群难度 | AR24: 二级难度 | AX24: 人群难度 | AZ24: 二级难度
B25: 问卷难度 | C25: 20题以内 | G25: =AVERAGE(G30:G45) -> 10.529116 | J25: 问卷难度 | L25: 21~30题 | R25: 问卷难度 | T25: 31~40题 | Z25: 问卷难度 | AB25: 41~50题 | AH25: 问卷难度 | AJ25: 51~60 | AP25: 问卷难度 | AR25: 61~70 | AX25: 问卷难度 | AZ25: 71~80
B26: 单价 | D26: =D3+1 -> 3 | G26: 成本 | H26: 上限 | J26: 单价 | L26: =L3+1 -> 4 | O26: =AVERAGE(O30:O45) -> 12.189754 | R26: 单价 | T26: =T3+1 -> 5 | W26: =AVERAGE(W30:W45) -> 13.850392 | Z26: 单价 | AB26: =AB3+1 -> 6 | AE26: =AVERAGE(AE30:AE45) -> 15.300634 | AH26: 单价 | AJ26: =AJ3+1 -> 7 | AM26: =AVERAGE(AM30:AM45) -> 16.961272 | AP26: 单价 | AR26: =AR3+1 -> 8 | AU26: =AVERAGE(AU30:AU45) -> 18.62191 | AX26: 单价 | AZ26: =AZ3+1 -> 9 | BC26: =AVERAGE(BC30:BC45) -> 20.282548 | BE26: =AVERAGE(BC26,AU26,AM26,AE26,W26,O26,G26) -> 16.201085 | BF26: =BE26-AVERAGE(AZ26,AR26,AJ26,AB26,T26,L26,D26) -> 10.201085
B27: 份数 | C27: P5 | D27: P4 | E27: P3 | F27: 实习生 | J27: 份数 | K27: P5 | L27: P4 | M27: P3 | N27: 实习生 | O27: 成本 | R27: 份数 | S27: P5 | T27: P4 | U27: P3 | V27: 实习生 | W27: 成本 | Z27: 份数 | AA27: P5 | AB27: P4 | AC27: P3 | AD27: 实习生 | AH27: 份数 | AI27: P5 | AJ27: P4 | AK27: P3 | AL27: 实习生 | AP27: 份数 | AR27: P4 | AS27: P3 | AT27: 实习生 | AX27: 份数 | AZ27: P4 | BA27: P3 | BB27: 实习生
B28: 0 | D28: 0 | E28: 0 | F28: =F51 -> 0 | G28: =(C28*5900+E28*3400+F28*300+B28*$D$26)/B28 -> #DIV/0! | J28: 0 | K28: =S28 -> 0 | L28: 0 | M28: 0 | N28: =N51 -> 0 | O28: =(K28*5900+M28*3400+N28*300+J28*$L$26)/J28 -> #DIV/0! | R28: 0 | S28: 0 | T28: 0 | U28: 0 | V28: =V51 -> 0 | W28: =(S28*5900+U28*3400+V28*300+R28*$T$26)/R28 -> #DIV/0! | Z28: 0 | AA28: =S28 -> 0 | AB28: 0 | AC28: 0 | AD28: =AD51 -> 0.1 | AE28: =(AA28*5900+AC28*3400+AD28*300+Z28*$AB$26)/Z28 -> #DIV/0! | AH28: 0 | AI28: =S28 -> 0 | AJ28: 0 | AK28: 0 | AL28: =AL51 -> 0.2 | AM28: =(AI28*5900+AK28*3400+AL28*300+AH28*$AJ$26)/AH28 -> #DIV/0! | AP28: 0 | AQ28: =AI28 -> 0 | AR28: 0 | AS28: 0 | AT28: =AT51 -> 0.3 | AU28: =(AQ28*5900+AS28*3400+AT28*300+AP28*$AR$26)/AP28 -> #DIV/0! | AX28: 0 | AY28: =AQ28 -> 0 | AZ28: 0 | BA28: 0 | BB28: =BB51 -> 0.4 | BC28: =(AY28*5900+BA28*3400+BB28*300+AX28*$AZ$26)/AX28 -> #DIV/0!
A29: 100份及以下 | B29: 1 | C29: =K29 -> 0 | D29: 0 | E29: =E52-0.1 -> 0.4 | F29: =F52 -> 0.6 | G29: =(C29*5900+E29*3400+F29*300+$D$26*B29)/B29 -> 1543 | J29: 1 | K29: =S29 -> 0 | L29: 0 | M29: =E29+0.1 -> 0.5 | N29: =N52 -> 0.7 | O29: =(K29*5900+M29*3400+N29*300+$L$26*J29)/J29 -> 1914 | R29: 1 | S29: 0 | T29: 0 | U29: =M29+0.1 -> 0.6 | V29: =V52 -> 0.8 | W29: =(S29*5900+U29*3400+V29*300+$T$26*R29)/R29 -> 2285 | Z29: 1 | AA29: =S29 -> 0 | AB29: 0 | AC29: =U29+0.1 -> 0.7 | AD29: =AD52 -> 0.9 | AE29: =(AA29*5900+AC29*3400+AD29*300+$AB$26*Z29)/Z29 -> 2656 | AH29: 1 | AI29: =S29 -> 0 | AJ29: 0 | AK29: =AC29+0.1 -> 0.8 | AL29: =AL52 -> 1 | AM29: =(AI29*5900+AK29*3400+AL29*300+$AJ$26*AH29)/AH29 -> 3027 | AP29: 1 | AQ29: =AI29 -> 0 | AR29: 0 | AS29: =AK29+0.1 -> 0.9 | AT29: =AT52 -> 1.1 | AU29: =(AQ29*5900+AS29*3400+AT29*300+$AR$26*AP29)/AP29 -> 3398 | AX29: 1 | AY29: =AQ29 -> 0 | AZ29: =AZ30 -> 0 | BA29: =BA30 -> 0.9 | BB29: =BB30 -> 1.2 | BC29: =(AY29*5900+BA29*3400+BB29*300+$AZ$26*AX29)/AX29 -> 3429
A30: 101~200份 | B30: 101 | C30: =K30 -> 0 | D30: 0 | E30: =E53-0.1 -> 0.4 | F30: =F53 -> 0.6 | G30: =(C30*5900+E30*3400+F30*300+$D$26*B30)/B30 -> 18.247525 | J30: 101 | K30: =S30 -> 0 | L30: 0 | M30: =E30+0.1 -> 0.5 | N30: =N53 -> 0.7 | O30: =(K30*5900+M30*3400+N30*300+$L$26*J30)/J30 -> 22.910891 | R30: 101 | S30: 0 | T30: 0 | U30: =M30+0.1 -> 0.6 | V30: =V53 -> 0.8 | W30: =(S30*5900+U30*3400+V30*300+$T$26*R30)/R30 -> 27.574257 | Z30: 101 | AA30: =S30 -> 0 | AB30: 0 | AC30: 0.6 | AD30: =AD53 -> 0.9 | AE30: =(AA30*5900+AC30*3400+AD30*300+$AB$26*Z30)/Z30 -> 28.871287 | AH30: 101 | AI30: =S30 -> 0 | AJ30: 0 | AK30: 0.7 | AL30: =AL53 -> 1 | AM30: =(AI30*5900+AK30*3400+AL30*300+$AJ$26*AH30)/AH30 -> 33.534653 | AP30: 101 | AQ30: =AI30 -> 0 | AR30: 0 | AS30: =AK30+0.1 -> 0.8 | AT30: =AT53 -> 1.1 | AU30: =(AQ30*5900+AS30*3400+AT30*300+$AR$26*AP30)/AP30 -> 38.19802 | AX30: 101 | AY30: =AQ30 -> 0 | AZ30: 0 | BA30: =AS30+0.1 -> 0.9 | BB30: =BB53 -> 1.2 | BC30: =(AY30*5900+BA30*3400+BB30*300+$AZ$26*AX30)/AX30 -> 42.861386
A31: 201~300份 | B31: 201 | C31: =K31 -> 0 | D31: 0.2 | E31: =E54-0.1 -> 0.7 | F31: =F54 -> 1 | G31: =(C31*5900+E31*3400+F31*300+$D$26*B31)/B31 -> 16.333333 | J31: 201 | K31: =S31 -> 0 | L31: 0.2 | M31: =E31+0.1 -> 0.8 | N31: =N54 -> 1.1 | O31: =(K31*5900+M31*3400+N31*300+$L$26*J31)/J31 -> 19.174129 | R31: 201 | S31: 0 | T31: 0.2 | U31: =M31+0.1 -> 0.9 | V31: =V54 -> 1.2 | W31: =(S31*5900+U31*3400+V31*300+$T$26*R31)/R31 -> 22.014925 | Z31: 201 | AA31: =S31 -> 0 | AB31: 0.2 | AC31: =U31+0.1 -> 1 | AD31: =AD54 -> 1.3 | AE31: =(AA31*5900+AC31*3400+AD31*300+$AB$26*Z31)/Z31 -> 24.855721 | AH31: 201 | AI31: =S31 -> 0 | AJ31: 0.2 | AK31: =AC31+0.1 -> 1.1 | AL31: =AL54 -> 1.4 | AM31: =(AI31*5900+AK31*3400+AL31*300+$AJ$26*AH31)/AH31 -> 27.696517 | AP31: 201 | AQ31: =AI31 -> 0 | AR31: 0.2 | AS31: =AK31+0.1 -> 1.2 | AT31: =AT54 -> 1.5 | AU31: =(AQ31*5900+AS31*3400+AT31*300+$AR$26*AP31)/AP31 -> 30.537313 | AX31: 201 | AY31: =AQ31 -> 0 | AZ31: 0.2 | BA31: =AS31+0.1 -> 1.3 | BB31: =BB54 -> 1.6 | BC31: =(AY31*5900+BA31*3400+BB31*300+$AZ$26*AX31)/AX31 -> 33.378109
A32: 301~500份 | B32: 301 | C32: =K32 -> 0 | D32: 0.2 | E32: =E55-0.1 -> 0.9 | F32: =F55 -> 1.1 | G32: =(C32*5900+E32*3400+F32*300+$D$26*B32)/B32 -> 14.262458 | J32: 301 | K32: =S32 -> 0 | L32: 0.2 | M32: =E32+0.1 -> 1 | N32: =N55 -> 1.2 | O32: =(K32*5900+M32*3400+N32*300+$L$26*J32)/J32 -> 16.491694 | R32: 301 | S32: 0 | T32: 0.2 | U32: =M32+0.1 -> 1.1 | V32: =V55 -> 1.3 | W32: =(S32*5900+U32*3400+V32*300+$T$26*R32)/R32 -> 18.72093 | Z32: 301 | AA32: =S32 -> 0 | AB32: 0.2 | AC32: =U32+0.1 -> 1.2 | AD32: =AD55 -> 1.4 | AE32: =(AA32*5900+AC32*3400+AD32*300+$AB$26*Z32)/Z32 -> 20.950166 | AH32: 301 | AI32: =S32 -> 0 | AJ32: 0.2 | AK32: =AC32+0.1 -> 1.3 | AL32: =AL55 -> 1.5 | AM32: =(AI32*5900+AK32*3400+AL32*300+$AJ$26*AH32)/AH32 -> 23.179402 | AP32: 301 | AQ32: =AI32 -> 0 | AR32: 0.2 | AS32: =AK32+0.1 -> 1.4 | AT32: =AT55 -> 1.6 | AU32: =(AQ32*5900+AS32*3400+AT32*300+$AR$26*AP32)/AP32 -> 25.408638 | AX32: 301 | AY32: =AQ32 -> 0 | AZ32: 0.2 | BA32: =AS32+0.1 -> 1.5 | BB32: =BB55 -> 1.7 | BC32: =(AY32*5900+BA32*3400+BB32*300+$AZ$26*AX32)/AX32 -> 27.637874
A33: 501~700份 | B33: 501 | C33: =K33 -> 0 | D33: 0.2 | E33: =E56-0.1 -> 1.2 | F33: =F56 -> 1.2 | G33: =(C33*5900+E33*3400+F33*300+$D$26*B33)/B33 -> 11.862275 | J33: 501 | K33: =S33 -> 0 | L33: 0.2 | M33: =E33+0.1 -> 1.3 | N33: =N56 -> 1.3 | O33: =(K33*5900+M33*3400+N33*300+$L$26*J33)/J33 -> 13.600798 | R33: 501 | S33: =S56-0.1 -> 0 | T33: 0.2 | U33: =M33+0.1 -> 1.4 | V33: =V56 -> 1.4 | W33: =(S33*5900+U33*3400+V33*300+$T$26*R33)/R33 -> 15.339321 | Z33: 501 | AA33: =S33 -> 0 | AB33: 0.2 | AC33: =U33+0.1 -> 1.5 | AD33: =AD56 -> 1.5 | AE33: =(AA33*5900+AC33*3400+AD33*300+$AB$26*Z33)/Z33 -> 17.077844 | AH33: 501 | AI33: =S33 -> 0 | AJ33: 0.2 | AK33: =AC33+0.1 -> 1.6 | AL33: =AL56 -> 1.6 | AM33: =(AI33*5900+AK33*3400+AL33*300+$AJ$26*AH33)/AH33 -> 18.816367 | AP33: 501 | AQ33: =AI33 -> 0 | AR33: 0.2 | AS33: =AK33+0.1 -> 1.7 | AT33: =AT56 -> 1.7 | AU33: =(AQ33*5900+AS33*3400+AT33*300+$AR$26*AP33)/AP33 -> 20.55489 | AX33: 501 | AY33: =AQ33 -> 0 | AZ33: 0.2 | BA33: =AS33+0.1 -> 1.8 | BB33: =BB56 -> 1.8 | BC33: =(AY33*5900+BA33*3400+BB33*300+$AZ$26*AX33)/AX33 -> 22.293413
A34: 701~900份 | B34: 701 | C34: =K34 -> 0.1 | D34: 0.2 | E34: =E57-0.1 -> 1.4 | F34: =F57 -> 1.3 | G34: =(C34*5900+E34*3400+F34*300+$D$26*B34)/B34 -> 11.188302 | J34: 701 | K34: =S34 -> 0.1 | L34: 0.2 | M34: =E34+0.1 -> 1.5 | N34: =N57 -> 1.4 | O34: =(K34*5900+M34*3400+N34*300+$L$26*J34)/J34 -> 12.71612 | R34: 701 | S34: =S57 -> 0.1 | T34: 0.2 | U34: =M34+0.1 -> 1.6 | V34: =V57 -> 1.5 | W34: =(S34*5900+U34*3400+V34*300+$T$26*R34)/R34 -> 14.243937 | Z34: 701 | AA34: =S34 -> 0.1 | AB34: 0.2 | AC34: =U34+0.1 -> 1.7 | AD34: =AD57 -> 1.6 | AE34: =(AA34*5900+AC34*3400+AD34*300+$AB$26*Z34)/Z34 -> 15.771755 | AH34: 701 | AI34: =S34 -> 0.1 | AJ34: 0.2 | AK34: =AC34+0.1 -> 1.8 | AL34: =AL57 -> 1.7 | AM34: =(AI34*5900+AK34*3400+AL34*300+$AJ$26*AH34)/AH34 -> 17.299572 | AP34: 701 | AQ34: =AI34 -> 0.1 | AR34: 0.2 | AS34: =AK34+0.1 -> 1.9 | AT34: =AT57 -> 1.8 | AU34: =(AQ34*5900+AS34*3400+AT34*300+$AR$26*AP34)/AP34 -> 18.827389 | AX34: 701 | AY34: =AQ34 -> 0.1 | AZ34: 0.2 | BA34: =AS34+0.1 -> 2 | BB34: =BB57 -> 1.9 | BC34: =(AY34*5900+BA34*3400+BB34*300+$AZ$26*AX34)/AX34 -> 20.355207
A35: 901~1000份 | B35: 901 | C35: =K35 -> 0 | D35: 0.3 | E35: =E58-0.1 -> 1.7 | F35: =F58 -> 1.3 | G35: =(C35*5900+E35*3400+F35*300+$D$26*B35)/B35 -> 9.8479467 | J35: 901 | K35: =S35 -> 0 | L35: 0.3 | M35: =E35+0.1 -> 1.8 | N35: =N58 -> 1.4 | O35: =(K35*5900+M35*3400+N35*300+$L$26*J35)/J35 -> 11.258602 | R35: 901 | S35: =S58-0.1 -> 0 | T35: 0.3 | U35: =M35+0.1 -> 1.9 | V35: =V58 -> 1.5 | W35: =(S35*5900+U35*3400+V35*300+$T$26*R35)/R35 -> 12.669256 | Z35: 901 | AA35: =S35 -> 0 | AB35: 0.3 | AC35: =U35+0.1 -> 2 | AD35: =AD58 -> 1.6 | AE35: =(AA35*5900+AC35*3400+AD35*300+$AB$26*Z35)/Z35 -> 14.079911 | AH35: 901 | AI35: =S35 -> 0 | AJ35: 0.3 | AK35: =AC35+0.1 -> 2.1 | AL35: =AL58 -> 1.7 | AM35: =(AI35*5900+AK35*3400+AL35*300+$AJ$26*AH35)/AH35 -> 15.490566 | AP35: 901 | AQ35: =AI35 -> 0 | AR35: 0.3 | AS35: =AK35+0.1 -> 2.2 | AT35: =AT58 -> 1.8 | AU35: =(AQ35*5900+AS35*3400+AT35*300+$AR$26*AP35)/AP35 -> 16.901221 | AX35: 901 | AY35: =AQ35 -> 0 | AZ35: 0.3 | BA35: =AS35+0.1 -> 2.3 | BB35: =BB58 -> 1.9 | BC35: =(AY35*5900+BA35*3400+BB35*300+$AZ$26*AX35)/AX35 -> 18.311876
A36: 1001~1200份 | B36: 1001 | C36: =K36 -> 0.1 | D36: 0.4 | E36: =E59-0.1 -> 1.9 | F36: =F59 -> 1.5 | G36: =(C36*5900+E36*3400+F36*300+$D$26*B36)/B36 -> 10.492507 | J36: 1001 | K36: =S36 -> 0.1 | L36: 0.4 | M36: =E36+0.1 -> 2 | N36: =N59 -> 1.6 | O36: =(K36*5900+M36*3400+N36*300+$L$26*J36)/J36 -> 11.862138 | R36: 1001 | S36: =S59-0.1 -> 0.1 | T36: 0.4 | U36: =M36+0.1 -> 2.1 | V36: =V59 -> 1.7 | W36: =(S36*5900+U36*3400+V36*300+$T$26*R36)/R36 -> 13.231768 | Z36: 1001 | AA36: =S36 -> 0.1 | AB36: 0.4 | AC36: =U36+0.1 -> 2.2 | AD36: =AD59 -> 1.8 | AE36: =(AA36*5900+AC36*3400+AD36*300+$AB$26*Z36)/Z36 -> 14.601399 | AH36: 1001 | AI36: =S36 -> 0.1 | AJ36: 0.4 | AK36: =AC36+0.1 -> 2.3 | AL36: =AL59 -> 1.9 | AM36: =(AI36*5900+AK36*3400+AL36*300+$AJ$26*AH36)/AH36 -> 15.971029 | AP36: 1001 | AQ36: =AI36 -> 0.1 | AR36: 0.4 | AS36: =AK36+0.1 -> 2.4 | AT36: =AT59 -> 2 | AU36: =(AQ36*5900+AS36*3400+AT36*300+$AR$26*AP36)/AP36 -> 17.340659 | AX36: 1001 | AY36: =AQ36 -> 0.1 | AZ36: 0.4 | BA36: =AS36+0.1 -> 2.5 | BB36: =BB59 -> 2.1 | BC36: =(AY36*5900+BA36*3400+BB36*300+$AZ$26*AX36)/AX36 -> 18.71029
A37: 1201~1400份 | B37: 1201 | C37: =K37 -> 0.1 | D37: 0.5 | E37: =E60-0.1 -> 2 | F37: =F60 -> 1.7 | G37: =(C37*5900+E37*3400+F37*300+$D$26*B37)/B37 -> 9.5778518 | J37: 1201 | K37: =S37 -> 0.1 | L37: 0.5 | M37: =E37+0.1 -> 2.1 | N37: =N60 -> 1.8 | O37: =(K37*5900+M37*3400+N37*300+$L$26*J37)/J37 -> 10.885928 | R37: 1201 | S37: =S60-0.1 -> 0.1 | T37: 0.5 | U37: =M37+0.1 -> 2.2 | V37: =V60 -> 1.9 | W37: =(S37*5900+U37*3400+V37*300+$T$26*R37)/R37 -> 12.194005 | Z37: 1201 | AA37: =S37 -> 0.1 | AB37: 0.5 | AC37: =U37+0.1 -> 2.3 | AD37: =AD60 -> 2 | AE37: =(AA37*5900+AC37*3400+AD37*300+$AB$26*Z37)/Z37 -> 13.502082 | AH37: 1201 | AI37: =S37 -> 0.1 | AJ37: 0.5 | AK37: =AC37+0.1 -> 2.4 | AL37: =AL60 -> 2.1 | AM37: =(AI37*5900+AK37*3400+AL37*300+$AJ$26*AH37)/AH37 -> 14.810158 | AP37: 1201 | AQ37: =AI37 -> 0.1 | AR37: 0.5 | AS37: =AK37+0.1 -> 2.5 | AT37: =AT60 -> 2.2 | AU37: =(AQ37*5900+AS37*3400+AT37*300+$AR$26*AP37)/AP37 -> 16.118235 | AX37: 1201 | AY37: =AQ37 -> 0.1 | AZ37: 0.5 | BA37: =AS37+0.1 -> 2.6 | BB37: =BB60 -> 2.3 | BC37: =(AY37*5900+BA37*3400+BB37*300+$AZ$26*AX37)/AX37 -> 17.426311
A38: 1401~1600份 | B38: 1401 | C38: =K38 -> 0.1 | D38: 0.5 | E38: =E61-0.1 -> 2.1 | F38: =F61 -> 1.8 | G38: =(C38*5900+E38*3400+F38*300+$D$26*B38)/B38 -> 8.9029265 | J38: 1401 | K38: =S38 -> 0.1 | L38: 0.5 | M38: =E38+0.1 -> 2.2 | N38: =N61 -> 1.9 | O38: =(K38*5900+M38*3400+N38*300+$L$26*J38)/J38 -> 10.167024 | R38: 1401 | S38: =S61-0.1 -> 0.1 | T38: 0.5 | U38: =M38+0.1 -> 2.3 | V38: =V61 -> 2 | W38: =(S38*5900+U38*3400+V38*300+$T$26*R38)/R38 -> 11.431121 | Z38: 1401 | AA38: =S38 -> 0.1 | AB38: 0.5 | AC38: =U38+0.1 -> 2.4 | AD38: =AD61 -> 2.1 | AE38: =(AA38*5900+AC38*3400+AD38*300+$AB$26*Z38)/Z38 -> 12.695218 | AH38: 1401 | AI38: =S38 -> 0.1 | AJ38: 0.5 | AK38: =AC38+0.1 -> 2.5 | AL38: =AL61 -> 2.2 | AM38: =(AI38*5900+AK38*3400+AL38*300+$AJ$26*AH38)/AH38 -> 13.959315 | AP38: 1401 | AQ38: =AI38 -> 0.1 | AR38: 0.5 | AS38: =AK38+0.1 -> 2.6 | AT38: =AT61 -> 2.3 | AU38: =(AQ38*5900+AS38*3400+AT38*300+$AR$26*AP38)/AP38 -> 15.223412 | AX38: 1401 | AY38: =AQ38 -> 0.1 | AZ38: 0.5 | BA38: =AS38+0.1 -> 2.7 | BB38: =BB61 -> 2.4 | BC38: =(AY38*5900+BA38*3400+BB38*300+$AZ$26*AX38)/AX38 -> 16.487509
A39: 1601~1800份 | B39: 1601 | C39: =K39 -> 0.1 | D39: 0.6 | E39: =E62-0.1 -> 2.3 | F39: =F62 -> 1.8 | G39: =(C39*5900+E39*3400+F39*300+$D$26*B39)/B39 -> 8.5902561 | J39: 1601 | K39: =S39 -> 0.1 | L39: 0.6 | M39: =E39+0.1 -> 2.4 | N39: =N62 -> 1.9 | O39: =(K39*5900+M39*3400+N39*300+$L$26*J39)/J39 -> 9.8213616 | R39: 1601 | S39: =S62-0.1 -> 0.1 | T39: 0.6 | U39: =M39+0.1 -> 2.5 | V39: =V62 -> 2 | W39: =(S39*5900+U39*3400+V39*300+$T$26*R39)/R39 -> 11.052467 | Z39: 1601 | AA39: =S39 -> 0.1 | AB39: 0.6 | AC39: =U39+0.1 -> 2.6 | AD39: =AD62 -> 2.1 | AE39: =(AA39*5900+AC39*3400+AD39*300+$AB$26*Z39)/Z39 -> 12.283573 | AH39: 1601 | AI39: =S39 -> 0.1 | AJ39: 0.6 | AK39: =AC39+0.1 -> 2.7 | AL39: =AL62 -> 2.2 | AM39: =(AI39*5900+AK39*3400+AL39*300+$AJ$26*AH39)/AH39 -> 13.514678 | AP39: 1601 | AQ39: =AI39 -> 0.1 | AR39: 0.6 | AS39: =AK39+0.1 -> 2.8 | AT39: =AT62 -> 2.3 | AU39: =(AQ39*5900+AS39*3400+AT39*300+$AR$26*AP39)/AP39 -> 14.745784 | AX39: 1601 | AY39: =AQ39 -> 0.1 | AZ39: 0.6 | BA39: =AS39+0.1 -> 2.9 | BB39: =BB62 -> 2.4 | BC39: =(AY39*5900+BA39*3400+BB39*300+$AZ$26*AX39)/AX39 -> 15.976889
A40: 1801~2000份 | B40: 1801 | C40: =K40 -> 0.1 | D40: 0.6 | E40: =E63-0.1 -> 2.5 | F40: =F63 -> 1.8 | G40: =(C40*5900+E40*3400+F40*300+$D$26*B40)/B40 -> 8.3470294 | J40: 1801 | K40: =S40 -> 0.1 | L40: 0.6 | M40: =E40+0.1 -> 2.6 | N40: =N63 -> 1.9 | O40: =(K40*5900+M40*3400+N40*300+$L$26*J40)/J40 -> 9.5524708 | R40: 1801 | S40: =S63-0.1 -> 0.1 | T40: 0.6 | U40: =M40+0.1 -> 2.7 | V40: =V63 -> 2 | W40: =(S40*5900+U40*3400+V40*300+$T$26*R40)/R40 -> 10.757912 | Z40: 1801 | AA40: =S40 -> 0.1 | AB40: 0.6 | AC40: =U40+0.1 -> 2.8 | AD40: =AD63 -> 2.1 | AE40: =(AA40*5900+AC40*3400+AD40*300+$AB$26*Z40)/Z40 -> 11.963354 | AH40: 1801 | AI40: =S40 -> 0.1 | AJ40: 0.6 | AK40: =AC40+0.1 -> 2.9 | AL40: =AL63 -> 2.2 | AM40: =(AI40*5900+AK40*3400+AL40*300+$AJ$26*AH40)/AH40 -> 13.168795 | AP40: 1801 | AQ40: =AI40 -> 0.1 | AR40: 0.6 | AS40: =AK40+0.1 -> 3 | AT40: =AT63 -> 2.3 | AU40: =(AQ40*5900+AS40*3400+AT40*300+$AR$26*AP40)/AP40 -> 14.374237 | AX40: 1801 | AY40: =AQ40 -> 0.1 | AZ40: 0.6 | BA40: =AS40+0.1 -> 3.1 | BB40: =BB63 -> 2.4 | BC40: =(AY40*5900+BA40*3400+BB40*300+$AZ$26*AX40)/AX40 -> 15.579678
A41: 2001~2200份 | B41: 2001 | C41: =K41 -> 0.2 | D41: 0.7 | E41: =E64-0.1 -> 2.7 | F41: =F64 -> 2 | G41: =(C41*5900+E41*3400+F41*300+$D$26*B41)/B41 -> 8.4772614 | J41: 2001 | K41: =S41 -> 0.2 | L41: 0.7 | M41: =E41+0.1 -> 2.8 | N41: =N64 -> 2.1 | O41: =(K41*5900+M41*3400+N41*300+$L$26*J41)/J41 -> 9.6621689 | R41: 2001 | S41: =S64-0.1 -> 0.2 | T41: 0.7 | U41: =M41+0.1 -> 2.9 | V41: =V64 -> 2.2 | W41: =(S41*5900+U41*3400+V41*300+$T$26*R41)/R41 -> 10.847076 | Z41: 2001 | AA41: =S41 -> 0.2 | AB41: 0.7 | AC41: =U41+0.1 -> 3 | AD41: =AD64 -> 2.3 | AE41: =(AA41*5900+AC41*3400+AD41*300+$AB$26*Z41)/Z41 -> 12.031984 | AH41: 2001 | AI41: =S41 -> 0.2 | AJ41: 0.7 | AK41: =AC41+0.1 -> 3.1 | AL41: =AL64 -> 2.4 | AM41: =(AI41*5900+AK41*3400+AL41*300+$AJ$26*AH41)/AH41 -> 13.216892 | AP41: 2001 | AQ41: =AI41 -> 0.2 | AR41: 0.7 | AS41: =AK41+0.1 -> 3.2 | AT41: =AT64 -> 2.5 | AU41: =(AQ41*5900+AS41*3400+AT41*300+$AR$26*AP41)/AP41 -> 14.401799 | AX41: 2001 | AY41: =AQ41 -> 0.2 | AZ41: 0.7 | BA41: =AS41+0.1 -> 3.3 | BB41: =BB64 -> 2.6 | BC41: =(AY41*5900+BA41*3400+BB41*300+$AZ$26*AX41)/AX41 -> 15.586707
...

Sheet 【注】使用说明&目录
B3: 【UX】研究资源成本估算工具v1.0
C5: 一、使用说明
C6: 1. 此工具用于对“UX研究资源”的使用成本进行标准化估算，成本结构包含“资源中台人力+发包相关费用”； 2. 前台可根据产品的研究需求，在对应的资源模块下进行变量配置，从而会自动得出成本估算结果； 3. 会能够更精准的估算资源成本，以及对资源做精细化运营，此表对部分资源增加了“难度等级”判定，可跳转难度等级页查看定义标准； 4. 当前可能会出现需求场景未穷尽情况，若自身需求无法在表中匹配，则可联系资源中台进行人工评估（xiexin@corp.netease.com）； 【注】预估成本可作为项目预算的前置评估参考，实际成本建议与资源中台进行二次确认。
C11: 二、目录
C12: ① | D12: 【国内】研究资源成本估算
C13: ② | D13: 【海外】研究资源成本估算
C14: ③ | D14: 【国内】常规用户招募-难度等级评估
C15: ④ | D15: 【国内】特殊&小众用户招募-难度等级评估
C16: ⑤ | D16: 【国内】问卷调研-难度等级评估
C17: ⑥ | D17: 【概览】发包相关费用标准

Sheet 成本估算
N11: P5 | O11: 7200
N12: P3 | O12: 3000
N13: OP | O13: 1300
N14: 实习生 | O14: 300
M21: 国内

Sheet ①【国内】研究资源成本估算 (v1.0)
A1: 点击返回【使用说明&目录】
B2: 【UX】国内研究资源成本估算
A3: 玩家招募类 | B3: 1. 下表人力为预估值，实际可能会根据需求真实情况出现上、下浮动，对应职级人天投入浮动在0.5左右； 2. 下表估算人力包含“甄别/邀约”工作，若前台自主执行“甄别/邀约”，则估算的P3及实习生人力减少20%； 3. 50人以上玩家招募需求由资源中台人工评估成本。 4.特殊用户默认混合执行，小众用户默认P3单独执行 5.16人规模以上的招募需求，默认使用【混合执行】报价 6.人力估值新增测试时长作为相关系数
B4: 点击跳转【常规用户-难度等级说明表】
B5: 点击跳转【特殊&小众用户-难度等级说明表】
A6: 服务编号 | B6: 样本类型 | C6: 测试方式 | D6: 难度等级 | F6: 测试时长 | H6: 需求执行人 | I6: 测试样本量 | K6: 测试时长系数转化 | L6: P5 | M6: P3 | N6: OP | O6: 实习生 | P6: 执行人力单价 | Q6: P5 | R6: P3 | S6: OP | T6: 实习生 | W6: 人力投入合计 | X6: 玩家礼金合计 | Y6: 招募费用合计 （视情况应用） | Z6: 甄别费用合计 | AA6: 执行人力单价
A7: GT001 | B7: 常规用户 （普通游戏玩家，无身份/职业限制要求） | C7: 实验室测试/座谈会 （广/杭/沪地区） | D7: 右侧下拉选择 需求难度 | E7: 三级难度 | F7: 右侧手动输入 测试时长 （单位:小时) （0.5为区间输入） | G7: 3 | H7: 混合执行 | I7: 右侧手动输入 测试样本量 （单位:个) | J7: 50 | K7: =IF(G7<2,0.8,IF(G7<=4,1,IF(AND(G7>4,G7<6),1.05,1.08))) -> 1 | L7: =Q7*K7 -> 1.04 | M7: =R7*K7 -> 3.6 | N7: =S7*K7 -> 5.225 | O7: =T7*K7 -> 9.48 | P7: =AA7 -> 549.8 | Q7: {=LOOKUP(1,0/(('【国内】用户招募成本估算（完整版）'!$D$4:$D$82=H7)*('【国内】用户招募成本估算（完整版）'!$E$4:$E$82=E7)*('【国内】用户招募成本估算（完整版）'!$C$4:$C$82=C7)*('【国内】用户招募成本估算（完整版）'!$B$4:$B$82=$B$7)),'【国内】用户招募成本估算（完整版）'!$H$4:$H$82)} -> 1.04 | R7: {=LOOKUP(1,0/(('【国内】用户招募成本估算（完整版）'!$D$4:$D$82=H7)*('【国内】用户招募成本估算（完整版）'!$E$4:$E$82=E7)*('【国内】用户招募成本估算（完整版）'!$C$4:$C$82=C7)*('【国内】用户招募成本估算（完整版）'!$B$4:$B$82=$B$7)),'【国内】用户招募成本估算（完整版）'!$I$4:$I$82)} -> 3.6 | S7: {=LOOKUP(1,0/(('【国内】用户招募成本估算（完整版）'!$D$4:$D$82=H7)*('【国内】用户招募成本估算（完整版）'!$E$4:$E$82=E7)*('【国内】用户招募成本估算（完整版）'!$C$4:$C$82=C7)*('【国内】用户招募成本估算（完整版）'!$B$4:$B$82=$B$7)),'【国内】用户招募成本估算（完整版）'!$J$4:$J$82)} -> 5.225 | T7: {=LOOKUP(1,0/(('【国内】用户招募成本估算（完整版）'!$D$4:$D$82=H7)*('【国内】用户招募成本估算（完整版）'!$E$4:$E$82=E7)*('【国内】用户招募成本估算（完整版）'!$C$4:$C$82=C7)*('【国内】用户招募成本估算（完整版）'!$B$4:$B$82=$B$7)),'【国内】用户招募成本估算（完整版）'!$K$4:$K$82)} -> 9.48 | W7: =L7+M7+N7+O7 -> 19.345 | X7: =IF($E$7="一级难度",'【国内】用户招募成本估算（完整版）'!M4,IF($E$7="二级难度",'【国内】用户招募成本估算（完整版）'!M5,IF($E$7="三级难度",'【国内】用户招募成本估算（完整版）'!M6,IF($E$7="四级难度",'【国内】用户招募成本估算（完整版）'!M7,IF($E$7="五级难度",'【国内】用户招募成本估算（完整版）'!M8,IF($E$7="六级难度",'【国内】用户招募成本估算（完整版）'!#REF!)))))) -> 15000 | Y7: =IF($E$7="一级难度",'【国内】用户招募成本估算（完整版）'!N4,IF($E$7="二级难度",'【国内】用户招募成本估算（完整版）'!N5,IF($E$7="三级难度",'【国内】用户招募成本估算（完整版）'!N6,IF($E$7="四级难度",'【国内】用户招募成本估算（完整版）'!N7,IF($E$7="五级难度",'【国内】用户招募成本估算（完整版）'!N8,IF($E$7="六级难度",'【国内】用户招募成本估算（完整版）'!#REF!)))))) -> 2500 | Z7: =J7*20 -> 1000 | AA7: =(L7*5900+M7*3400+N7*1200+O7*300)/J7 -> 549.8 | AB7: =P7*J7 -> 27490
